Workbook

Sheet 우리집
A1: ▣ 우리집 예상 공사비 (실시간 자동 산정)
A2: 총 공사비 (부가세 별도) | B2: =공사비산출!B3 | C2: 원
A3: 총 공사비 (부가세 포함) | B3: =공사비산출!B5 | C3: 원
A4: 평당 공사비 (부가세 별도) | B4: =공사비산출!E3 | C4: 원/평
A5: 본 시트의 항목을 입력하면 상단 총공사비가 실시간 갱신됩니다 (apt-planner v2)
A7: ▣ 1. 기본 정보
A8: 평형 (공급평, 자동산정 ← B13 또는 D13) | B8: 30 | C8: 평형은 B13(공급평)·D13(전용㎡) 중 하나만 입력. D13 우선. (2.4825 = 3.31 × 0.75)
A9: 베이수 (2/3/4/5) | B9: 3 | C9: 20평대=2~4 / 30평대=2~4 / 40평+=3~5
A10: 방 개수 (자동, 수정 가능) | B10: =IF(B8<22,2,IF(B8<32,3,IF(B8<45,4,5))) | C10: 평형 자동: <22:2 / <32:3 / <45:4 / 45+:5
A11: 공용욕실 개수 | B11: 1 | C11: 보통 1개
A12: 부부욕실 유무 (1=있음, 0=없음) | B12: 1 | C12: 평형 자동: <22:2 / <32:3 / <45:4 / 45+:5
A13: 욕실 총 개수 (자동) | B13: =B11+B12 | C13: 공용+부부 합산
A14: 공급면적 (㎡, 자동) | B14: =B8*3.31 | C14: 평*3.31
A15: 전용면적 (㎡, 자동) | B15: =B14*0.75 | C15: 공급*0.75
A16: 외부창 면적 (㎡, 자동) | B16: =INDEX(표준면적!$B$11:$G$11,1,MATCH(표준면적!$J$2,표준면적!$B$2:$G$2,0))+(INDEX(표준면적!$B$11:$G$11,1,MATCH(표준면적!$J$2,표준면적!$B$2:$G$2,0)+1)-INDEX(표준면적!$B$11:$G$11,1,MATCH(표준면적!$J$2,표준면적!$B$2:$G$2,0)))*표준면적!$J$4 | C16: 베이별 자동
A17: └─ 평형 직접 입력 (B13: 공급평 / D13: 전용㎡, 둘 중 하나) | B17: 30 | C17: ← 공급평(평) | 전용㎡(㎡) →
A18: ▣ 2. 공사범위 — 확장설정 + 공간별 시공 매트릭스
A19: 발코니 깊이 (m) | B19: 1.5 | C19: 표준 1.5m
A21: 공간 | B21: 현재 확장 상태 | C21: 확장 후 | D21: 바닥재 | E21: 도배 | F21: 몰딩/걸레받이 | G21: 에어컨 | H21: 붙박이장 | I21: 실링팬 | J21: 샷시 교체
A22: 거실 | B22: N | C22: Y | D22: Y | E22: Y | F22: Y | G22: Y | H22: - | I22: Y | J22: Y
A23: 주방 | B23: N | C23: Y | D23: Y | E23: Y | F23: Y | G23: - | H23: - | I23: - | J23: Y
A24: 안방 | B24: N | C24: N | D24: Y | E24: Y | F24: Y | G24: Y | H24: Y | I24: Y | J24: Y
A25: 작은방1 | B25: N | C25: Y | D25: Y | E25: Y | F25: Y | G25: Y | H25: Y | I25: - | J25: Y
A26: 작은방2 | B26: N | C26: Y | D26: Y | E26: Y | F26: Y | G26: - | H26: Y | I26: - | J26: Y
A28: ▣ 2. 공사범위 — 전체공종 토글 + 추가 옵션
A29: 항목 | B29: 값 | C29: 안내
A30: 철거공사 | B30: Y | C30: 전용면적 전체
A31: 난방배관 교체 | B31: N | C31: 노후 난방 엑셀파이프 전체 교체 (공급평 × 30만원). 철거 시 함께 권장.
A32: 단열공사 | B32: Y | C32: 전용면적 전체
A33: 샷시 교체 (자동 — 공간별 합산) | B33: =IF(COUNTIF(J22:J26,"Y")>0,"Y","N") | C33: 매트릭스 J열(공간별 샷시) 합산 자동. 공간별로 J에 입력하세요.
A34: 공용욕실 세트 | B34: Y | C34: 공용욕실 개수만큼
A35: 부부욕실 세트 | B35: Y | C35: 부부욕실 유무 (0/1)
A36: 주방가구 | B36: Y | C36: 3.6m 환산
A37: 중문 | B37: Y | C37: 1ea
A38: 일반가구(현관) | B38: Y | C38: 1ea
A39: 조명 풀세트 | B39: Y | C39: 1set (개별 등기구로 대체 시 N)
A40: 천정 목공사 | B40: N | C40: 거실 면적 기준
A41: 가벽 신설 길이 (m) | B41: 0 | C41: 가벽 신설 길이 입력 (m). 입력 시 목공사(길이×2.3㎡) + 양면 도배(길이×2.3×2㎡) 자동 산정. 0 또는 빈칸이면 산정 없음.
A42: 에어컨 실외기 (자동) | B42: =공사범위!B21 | C42: 시스템에어컨 ON 공간 있으면 자동 Y
A43: 샷시 (자동 — 확장 시 강제) | B43: =공사범위!B22 | C43: 외부창 면적 (전용 × 0.18). 확장 시 발코니 측 새 외부창은 자동 산정(산출 #82). 전체 샷시 교체 ON 시 비확장 공간 외부창만 추가.
...

Sheet 표준면적
A1: 평형별 공간 면적 표준치 (㎡) | I1: 🔢 보간 도우미
A2: 공간 | B2: 10 | C2: 20 | D2: 30 | E2: 40 | F2: 50 | G2: 60 | H2: 단위 | I2: lower 평형대 | J2: =MAX(10,MIN(50,INT(우리집!$B$8/10)*10))
A3: 거실 | B3: =CHOOSE(우리집!$B$9-1,B37,B49,B61,B73) | C3: =CHOOSE(우리집!$B$9-1,C37,C49,C61,C73) | D3: =CHOOSE(우리집!$B$9-1,D37,D49,D61,D73) | E3: =CHOOSE(우리집!$B$9-1,E37,E49,E61,E73) | F3: =CHOOSE(우리집!$B$9-1,F37,F49,F61,F73) | G3: =CHOOSE(우리집!$B$9-1,G37,G49,G61,G73) | H3: ㎡ | I3: upper 평형대 | J3: =J2+10
A4: 주방 | B4: =CHOOSE(우리집!$B$9-1,B38,B50,B62,B74) | C4: =CHOOSE(우리집!$B$9-1,C38,C50,C62,C74) | D4: =CHOOSE(우리집!$B$9-1,D38,D50,D62,D74) | E4: =CHOOSE(우리집!$B$9-1,E38,E50,E62,E74) | F4: =CHOOSE(우리집!$B$9-1,F38,F50,F62,F74) | G4: =CHOOSE(우리집!$B$9-1,G38,G50,G62,G74) | H4: ㎡ | I4: ratio (0~1) | J4: =MIN(1,MAX(0,(우리집!$B$8-J2)/10))
A5: 안방 | B5: =CHOOSE(우리집!$B$9-1,B39,B51,B63,B75) | C5: =CHOOSE(우리집!$B$9-1,C39,C51,C63,C75) | D5: =CHOOSE(우리집!$B$9-1,D39,D51,D63,D75) | E5: =CHOOSE(우리집!$B$9-1,E39,E51,E63,E75) | F5: =CHOOSE(우리집!$B$9-1,F39,F51,F63,F75) | G5: =CHOOSE(우리집!$B$9-1,G39,G51,G63,G75) | H5: ㎡
A6: 작은방1 | B6: =CHOOSE(우리집!$B$9-1,B40,B52,B64,B76) | C6: =CHOOSE(우리집!$B$9-1,C40,C52,C64,C76) | D6: =CHOOSE(우리집!$B$9-1,D40,D52,D64,D76) | E6: =CHOOSE(우리집!$B$9-1,E40,E52,E64,E76) | F6: =CHOOSE(우리집!$B$9-1,F40,F52,F64,F76) | G6: =CHOOSE(우리집!$B$9-1,G40,G52,G64,G76) | H6: ㎡
A7: 작은방2 | B7: =CHOOSE(우리집!$B$9-1,B41,B53,B65,B77) | C7: =CHOOSE(우리집!$B$9-1,C41,C53,C65,C77) | D7: =CHOOSE(우리집!$B$9-1,D41,D53,D65,D77) | E7: =CHOOSE(우리집!$B$9-1,E41,E53,E65,E77) | F7: =CHOOSE(우리집!$B$9-1,F41,F53,F65,F77) | G7: =CHOOSE(우리집!$B$9-1,G41,G53,G65,G77) | H7: ㎡
A8: 공용욕실 | B8: =CHOOSE(우리집!$B$9-1,B42,B54,B66,B78) | C8: =CHOOSE(우리집!$B$9-1,C42,C54,C66,C78) | D8: =CHOOSE(우리집!$B$9-1,D42,D54,D66,D78) | E8: =CHOOSE(우리집!$B$9-1,E42,E54,E66,E78) | F8: =CHOOSE(우리집!$B$9-1,F42,F54,F66,F78) | G8: =CHOOSE(우리집!$B$9-1,G42,G54,G66,G78) | H8: ㎡
A9: 부부욕실 | B9: =CHOOSE(우리집!$B$9-1,B43,B55,B67,B79) | C9: =CHOOSE(우리집!$B$9-1,C43,C55,C67,C79) | D9: =CHOOSE(우리집!$B$9-1,D43,D55,D67,D79) | E9: =CHOOSE(우리집!$B$9-1,E43,E55,E67,E79) | F9: =CHOOSE(우리집!$B$9-1,F43,F55,F67,F79) | G9: =CHOOSE(우리집!$B$9-1,G43,G55,G67,G79) | H9: ㎡
A10: 현관 | B10: =CHOOSE(우리집!$B$9-1,B44,B56,B68,B80) | C10: =CHOOSE(우리집!$B$9-1,C44,C56,C68,C80) | D10: =CHOOSE(우리집!$B$9-1,D44,D56,D68,D80) | E10: =CHOOSE(우리집!$B$9-1,E44,E56,E68,E80) | F10: =CHOOSE(우리집!$B$9-1,F44,F56,F68,F80) | G10: =CHOOSE(우리집!$B$9-1,G44,G56,G68,G80) | H10: ㎡
A11: 외부창 (3베이 기준) | B11: =CHOOSE(우리집!$B$9-1,B45,B57,B69,B81) | C11: =CHOOSE(우리집!$B$9-1,C45,C57,C69,C81) | D11: =CHOOSE(우리집!$B$9-1,D45,D57,D69,D81) | E11: =CHOOSE(우리집!$B$9-1,E45,E57,E69,E81) | F11: =CHOOSE(우리집!$B$9-1,F45,F57,F69,F81) | G11: =CHOOSE(우리집!$B$9-1,G45,G57,G69,G81) | H11: ㎡
A12: 공간 둘레 추정 (m, 몰딩용)
A13: 공간 | B13: 10 | C13: 20 | D13: 30 | E13: 40 | F13: 50 | G13: 60 | H13: 단위
A14: 거실 | B14: =IF(B3=0,0,SQRT(B3)*3.4) | C14: =IF(C3=0,0,SQRT(C3)*3.4) | D14: =IF(D3=0,0,SQRT(D3)*3.4) | E14: =IF(E3=0,0,SQRT(E3)*3.4) | F14: =IF(F3=0,0,SQRT(F3)*3.4) | G14: =IF(G3=0,0,SQRT(G3)*3.4) | H14: m
A15: 주방 | B15: =IF(B4=0,0,SQRT(B4)*3.4) | C15: =IF(C4=0,0,SQRT(C4)*3.4) | D15: =IF(D4=0,0,SQRT(D4)*3.4) | E15: =IF(E4=0,0,SQRT(E4)*3.4) | F15: =IF(F4=0,0,SQRT(F4)*3.4) | G15: =IF(G4=0,0,SQRT(G4)*3.4) | H15: m
A16: 안방 | B16: =IF(B5=0,0,SQRT(B5)*3.4) | C16: =IF(C5=0,0,SQRT(C5)*3.4) | D16: =IF(D5=0,0,SQRT(D5)*3.4) | E16: =IF(E5=0,0,SQRT(E5)*3.4) | F16: =IF(F5=0,0,SQRT(F5)*3.4) | G16: =IF(G5=0,0,SQRT(G5)*3.4) | H16: m
A17: 작은방1 | B17: =IF(B6=0,0,SQRT(B6)*3.4) | C17: =IF(C6=0,0,SQRT(C6)*3.4) | D17: =IF(D6=0,0,SQRT(D6)*3.4) | E17: =IF(E6=0,0,SQRT(E6)*3.4) | F17: =IF(F6=0,0,SQRT(F6)*3.4) | G17: =IF(G6=0,0,SQRT(G6)*3.4) | H17: m
A18: 작은방2 | B18: =IF(B7=0,0,SQRT(B7)*3.4) | C18: =IF(C7=0,0,SQRT(C7)*3.4) | D18: =IF(D7=0,0,SQRT(D7)*3.4) | E18: =IF(E7=0,0,SQRT(E7)*3.4) | F18: =IF(F7=0,0,SQRT(F7)*3.4) | G18: =IF(G7=0,0,SQRT(G7)*3.4) | H18: m
A19: 공용욕실 | B19: =IF(B8=0,0,SQRT(B8)*3.4) | C19: =IF(C8=0,0,SQRT(C8)*3.4) | D19: =IF(D8=0,0,SQRT(D8)*3.4) | E19: =IF(E8=0,0,SQRT(E8)*3.4) | F19: =IF(F8=0,0,SQRT(F8)*3.4) | G19: =IF(G8=0,0,SQRT(G8)*3.4) | H19: m
A20: 부부욕실 | B20: =IF(B9=0,0,SQRT(B9)*3.4) | C20: =IF(C9=0,0,SQRT(C9)*3.4) | D20: =IF(D9=0,0,SQRT(D9)*3.4) | E20: =IF(E9=0,0,SQRT(E9)*3.4) | F20: =IF(F9=0,0,SQRT(F9)*3.4) | G20: =IF(G9=0,0,SQRT(G9)*3.4) | H20: m
A21: 현관 | B21: =IF(B10=0,0,SQRT(B10)*3.4) | C21: =IF(C10=0,0,SQRT(C10)*3.4) | D21: =IF(D10=0,0,SQRT(D10)*3.4) | E21: =IF(E10=0,0,SQRT(E10)*3.4) | F21: =IF(F10=0,0,SQRT(F10)*3.4) | G21: =IF(G10=0,0,SQRT(G10)*3.4) | H21: m
A22: 외부창 (3베이 기준) | B22: =IF(B11=0,0,SQRT(B11)*3.4) | C22: =IF(C11=0,0,SQRT(C11)*3.4) | D22: =IF(D11=0,0,SQRT(D11)*3.4) | E22: =IF(E11=0,0,SQRT(E11)*3.4) | F22: =IF(F11=0,0,SQRT(F11)*3.4) | G22: =IF(G11=0,0,SQRT(G11)*3.4) | H22: m
A25: 발코니/다용도실 표준 면적 (3베이 비확장 가정)
A26: 공간 | B26: 10 | C26: 20 | D26: 30 | E26: 40 | F26: 50 | G26: 60 | H26: 단위
A27: 발코니 면적 | B27: 4 | C27: 7 | D27: 11 | E27: 15 | F27: 18 | G27: 22 | H27: ㎡
A28: 다용도실 면적 | B28: 1.5 | C28: 2.5 | D28: 3 | E28: 4 | F28: 4.5 | G28: 5 | H28: ㎡
A29: 발코니 도장 면적 | B29: 12 | C29: 21 | D29: 32 | E29: 43 | F29: 53 | G29: 64 | H29: ㎡
A30: 다용도실 도장 면적 | B30: 5 | C30: 8 | D30: 9 | E30: 12 | F30: 14 | G30: 15 | H30: ㎡
A31: 주의: 평형별 표준치는 한국 아파트 평균(전용 75/100/130㎡, 3베이 기준). 2026-05 시장 자료(대한건축학회·전용율 분포) 반영하여 거실·외부창 면적 보정. [베이별 산정] 우리집!B10 베이수에 따라 active 영역(B3:G11) 자동 갱신. 베이별 표는 row 35 이하 참조.
A33: ═══ [베이별 평형 표준면적] ═══ (active 영역 B3:G11이 우리집!B10에 따라 자동 참조)
A35: [2베이] 평형별 표준 면적 (㎡) | H35: 20~30평 권장 (40평+ 추정)
A36: 공간 | B36: 10 | C36: 20 | D36: 30 | E36: 40 | F36: 50 | G36: 60 | H36: 단위
A37: 거실 | B37: 8 | C37: 14 | D37: 24 | E37: 30 | F37: 34 | G37: 40 | H37: ㎡
A38: 주방 | B38: 5 | C38: 8 | D38: 11 | E38: 14 | F38: 16 | G38: 19 | H38: ㎡
A39: 안방 | B39: 7 | C39: 11 | D39: 15 | E39: 17 | F39: 18 | G39: 20 | H39: ㎡
A40: 작방1 | B40: 0 | C40: 8 | D40: 9 | E40: 10 | F40: 11 | G40: 13 | H40: ㎡
A41: 작방2 | B41: 0 | C41: 0 | D41: 7 | E41: 9 | F41: 10 | G41: 11 | H41: ㎡
A42: 공용욕실 | B42: 3 | C42: 4 | D42: 5 | E42: 6 | F42: 7 | G42: 8 | H42: ㎡
A43: 부부욕실 | B43: 0 | C43: 0 | D43: 5 | E43: 6 | F43: 7 | G43: 8 | H43: ㎡
A44: 현관 | B44: 2 | C44: 3 | D44: 4 | E44: 5 | F44: 6 | G44: 7 | H44: ㎡
...

Sheet 공사범위
A1: 공사범위 선택 (공간×공종 매트릭스, Y/N)
A2: 공간 | B2: 바닥재 | C2: 도배 | D2: 몰딩 | E2: 에어컨 | F2: 붙박이장 | G2: 실링팬
A3: 거실 | B3: =우리집!D22 | C3: =우리집!E22 | D3: =우리집!F22 | E3: =우리집!G22 | F3: =우리집!H22 | G3: =우리집!I22
A4: 주방 | B4: =우리집!D23 | C4: =우리집!E23 | D4: =우리집!F23 | E4: =우리집!G23 | F4: =우리집!H23 | G4: =우리집!I23
A5: 안방 | B5: =우리집!D24 | C5: =우리집!E24 | D5: =우리집!F24 | E5: =우리집!G24 | F5: =우리집!H24 | G5: =우리집!I24
A6: 작은방1 | B6: =우리집!D25 | C6: =우리집!E25 | D6: =우리집!F25 | E6: =우리집!G25 | F6: =우리집!H25 | G6: =우리집!I25
A7: 작은방2 | B7: =우리집!D26 | C7: =우리집!E26 | D7: =우리집!F26 | E7: =우리집!G26 | F7: =우리집!H26 | G7: =우리집!I26
A9: [전체 공종 — 단일 입력]
A10: 철거공사 | B10: =우리집!B30 | C10: 전용면적 전체
A11: 단열공사 | B11: =우리집!B32 | C11: 전용면적 전체
A12: 샷시 교체 | B12: =우리집!B33 | C12: 외부창 면적 (전용 × 0.18)
A13: 공용욕실 세트 | B13: =우리집!B34 | C13: 공용욕실 개수만큼
A14: 부부욕실 세트 | B14: =우리집!B35 | C14: 부부욕실 유무 (0/1)
A15: 주방가구 | B15: =우리집!B36 | C15: 3.6m 환산
A16: 중문 | B16: =우리집!B37 | C16: 1ea
A17: 일반가구(현관) | B17: =우리집!B38 | C17: 1ea
A18: 조명 풀세트 | B18: =우리집!B39 | C18: 1set (개별 등기구로 대체 시 N)
A19: 천정 목공사 | B19: =우리집!B40 | C19: 거실 면적 기준
A20: 가벽 신설 | B20: =우리집!B41 | C20: 1㎡ 가정
A21: 에어컨 실외기 (자동) | B21: =IF(COUNTIF(E3:E7,"Y")>0,"Y","N") | C21: 시스템에어컨 ON 공간 있으면 자동 Y
A22: 샷시 (자동 — 확장 시 강제) | B22: =B12 | C22: 외부창 면적 (전용 × 0.18). 확장 시 발코니 측 새 외부창은 자동 산정(산출 #82). 전체 샷시 교체 ON 시 비확장 공간 외부창만 추가.
A23: 스위치/콘센트 교체 | B23: =우리집!B44 | C23: 평형별 자동 산출 (10평 18ea → 30평 34ea → 60평 56ea)
A24: 인덕션 전용선 | B24: =우리집!B45 | C24: 220V 인덕션 전용선 신설 (분전반→주방, 50만원 기본)
A25: 구청 확장공사 신고 (도면+신고대행) | B25: =우리집!B46 | C25: 확장 시 권장 — 신고 미이행 시 과태료. 확장 없으면 자동 0원.
A26: 분배기 교체 | B26: =우리집!B47 | C26: 난방 분배기 교체 (50만원)
A27: 배관 변경 | B27: =우리집!B48 | C27: 주방 위치 변경 등 배관 변경 (50만원)
A28: 난방온도조절기 교체 | B28: =우리집!B49 | C28: 거실+방 자동 산정 (평형별 ea)
A29: 난방배관 교체 | B29: =우리집!B31 | C29: 공급평 × 30만원. 우리집 전체공종 토글 연동.

Sheet 욕실설정
A1: 욕실 컴포넌트 설정 (등급·적용여부)
A3: 컴포넌트 | B3: 공용욕실 등급 | C3: 부부욕실 등급 | D3: 공용 적용 | E3: 부부 적용
A4: 젠다이 | B4: =우리집!B87 | C4: =우리집!B101 | D4: =우리집!C87 | E4: =우리집!C101
A5: 방수 | B5: =우리집!B88 | C5: =우리집!B102 | D5: =우리집!C88 | E5: =우리집!C102
A6: 타일자재 | B6: =우리집!B89 | C6: =우리집!B103 | D6: =우리집!C89 | E6: =우리집!C103
A7: 타일시공 | B7: =우리집!B90 | C7: =우리집!B104 | D7: =우리집!C90 | E7: =우리집!C104
A8: 파티션 | B8: =우리집!B91 | C8: =우리집!B105 | D8: =우리집!C91 | E8: =우리집!C105
A9: 천정 | B9: =우리집!B92 | C9: =우리집!B106 | D9: =우리집!C92 | E9: =우리집!C106
A10: 세면대 | B10: =우리집!B93 | C10: =우리집!B107 | D10: =우리집!C93 | E10: =우리집!C107
A11: 수전 | B11: =우리집!B94 | C11: =우리집!B108 | D11: =우리집!C94 | E11: =우리집!C108
A12: 양변기 | B12: =우리집!B95 | C12: =우리집!B109 | D12: =우리집!C95 | E12: =우리집!C109
A13: 악세사리 | B13: =우리집!B96 | C13: =우리집!B110 | D13: =우리집!C96 | E13: =우리집!C110
A14: 줄눈 | B14: =우리집!B97 | C14: =우리집!B111 | D14: =우리집!C97 | E14: =우리집!C111
A15: 안내 | B15: 등급 셀에 '기본'을 두면 우리집 시트의 욕실 등급(공용 B16, 부부 B17)을 따릅니다. 특정 컴포넌트만 다른 등급을 원할 때 직접 가성비/표준/고급 선택. 적용 N으로 두면 해당 컴포넌트는 견적에서 제외됩니다. 악세사리 = 수건걸이+변기솔+청소수전 set. 줄눈 = 가성비(백시멘트)/표준(아덱스FG4)/고급(케라폭시 에폭시).

Sheet 주방설정
A1: 주방가구 컴포넌트 설정
A3: 컴포넌트 | B3: 등급 | C3: 적용여부
A4: 미드웨이 | B4: =우리집!B121 | C4: =우리집!C121
A5: 도어 (세트 통합 — 미사용) | B5: =우리집!B122 | C5: =우리집!C122
A6: 상판 | B6: =우리집!B123 | C6: =우리집!C123
A7: 하드웨어 | B7: =우리집!B124 | C7: =우리집!C124
A8: 후드 | B8: =우리집!B125 | C8: =우리집!C125
A9: 싱크볼 | B9: =우리집!B126 | C9: =우리집!C126
A10: 주방가구 세트 (몸체+도어) | B10: =우리집!B127 | C10: =우리집!C127
A12: 안내 | B12: 등급 셀에 '기본'을 두면 우리집 시트의 주방가구 등급(B18)을 따릅니다. 특정 컴포넌트만 다른 등급 원할 때 직접 지정. 적용 N으로 두면 견적에서 제외. 몸체·미드웨이·도어·상판: 우리집!B31의 주방가구 길이 × m당 단가. 하드웨어: 길이 × 4.5 set/m. 후드·싱크볼은 자재만 (시공은 주방가구 시공에 포함).

Sheet 확장설정
A1: 확장공사 설정 (베이 형태 + 공간별 확장 전/후)
A3: 베이 형태 | B3: =우리집!$B$9 | C3: 우리집!B10에서 자동 동기화 (직접 수정 X)
A4: 발코니 깊이 (m) | B4: =우리집!$B$19 | C4: 표준 1.5m. 단지별 차이 시 수정
A6: 공간 | B6: 베이별 폭(m) | C6: 발코니 면적(㎡) | D6: 확장 전 | E6: 확장 후 | F6: 추가확장(㎡)
A7: 거실 | B7: =SQRT(INDEX(표준면적!$B$3:$G$10,1,MATCH(표준면적!$J$2,표준면적!$B$2:$G$2,0))+(INDEX(표준면적!$B$3:$G$10,1,MATCH(표준면적!$J$2,표준면적!$B$2:$G$2,0)+1)-INDEX(표준면적!$B$3:$G$10,1,MATCH(표준면적!$J$2,표준면적!$B$2:$G$2,0)))*표준면적!$J$4)*(IF($B$3=2,1.4,IF($B$3=3,1,0.85))) | C7: =B7*$B$4 | D7: =우리집!B22 | E7: =우리집!C22 | F7: =IF(AND(D7="N",E7="Y"),C7,0)
A8: 안방 | B8: =SQRT(INDEX(표준면적!$B$3:$G$10,3,MATCH(표준면적!$J$2,표준면적!$B$2:$G$2,0))+(INDEX(표준면적!$B$3:$G$10,3,MATCH(표준면적!$J$2,표준면적!$B$2:$G$2,0)+1)-INDEX(표준면적!$B$3:$G$10,3,MATCH(표준면적!$J$2,표준면적!$B$2:$G$2,0)))*표준면적!$J$4)*(IF($B$3=2,1,IF($B$3=3,0.95,0.9))) | C8: =B8*$B$4 | D8: =우리집!B24 | E8: =우리집!C24 | F8: =IF(AND(D8="N",E8="Y"),C8,0)
A9: 작은방1 | B9: =SQRT(INDEX(표준면적!$B$3:$G$10,4,MATCH(표준면적!$J$2,표준면적!$B$2:$G$2,0))+(INDEX(표준면적!$B$3:$G$10,4,MATCH(표준면적!$J$2,표준면적!$B$2:$G$2,0)+1)-INDEX(표준면적!$B$3:$G$10,4,MATCH(표준면적!$J$2,표준면적!$B$2:$G$2,0)))*표준면적!$J$4)*(IF($B$3<=2,0,IF($B$3=3,0.9,0.8))) | C9: =B9*$B$4 | D9: =우리집!B25 | E9: =우리집!C25 | F9: =IF(AND(D9="N",E9="Y"),C9,0)
A10: 작은방2 | B10: =SQRT(INDEX(표준면적!$B$3:$G$10,5,MATCH(표준면적!$J$2,표준면적!$B$2:$G$2,0))+(INDEX(표준면적!$B$3:$G$10,5,MATCH(표준면적!$J$2,표준면적!$B$2:$G$2,0)+1)-INDEX(표준면적!$B$3:$G$10,5,MATCH(표준면적!$J$2,표준면적!$B$2:$G$2,0)))*표준면적!$J$4)*(IF($B$3<=2,0,IF($B$3=3,0.85,0.8))) | C10: =B10*$B$4 | D10: =우리집!B26 | E10: =우리집!C26 | F10: =IF(AND(D10="N",E10="Y"),C10,0)
A11: 주방 | B11: =SQRT(INDEX(표준면적!$B$3:$G$10,2,MATCH(표준면적!$J$2,표준면적!$B$2:$G$2,0))+(INDEX(표준면적!$B$3:$G$10,2,MATCH(표준면적!$J$2,표준면적!$B$2:$G$2,0)+1)-INDEX(표준면적!$B$3:$G$10,2,MATCH(표준면적!$J$2,표준면적!$B$2:$G$2,0)))*표준면적!$J$4)*(0.85) | C11: =B11*$B$4 | D11: =우리집!B23 | E11: =우리집!C23 | F11: =IF(AND(D11="N",E11="Y"),C11,0) | G11: 자동 ON/OFF
A12: 추가확장 합계 | F12: =SUM(F7:F11) | G12: =IF(F12>0,"Y","N")
A14: 안내 / [샷시 분리] 샷시는 발코니 면적 비율로 자동 분배: 확장 공간 외부창은 자동 산정(라인 #82, 토글 자동), 비확장 공간 외부창은 전체 샷시 교체 토글(공사범위!B25) ON 시 라인 #4에 산정. 확장공사 단가에는 샷시 미포함 — 골조+단열+배관+미장만. | B14: 한국 아파트 평면 구조 기준: 거실·안방·작은방1은 전면 베이, 주방·작은방2(3베이)는 후면 베이. 4베이 평면은 작은방2가 전면으로 이동. 베이 형태(B3)와 평형(우리집!B4)에 따라 폭이 자동 계산되고 × 깊이(B4)로 발코니 면적 산출. 확장 전 N + 확장 후 Y인 공간만 '추가확장 면적'(F열)으로 견적에 반영. 주방 default = 확장 전 N (다용도실 분리). 신축이면 D11=Y로 변경.

Sheet 공사비산출
A1: 공사비 산출 결과
A3: 총 공사비 | B3: =I11+I14+I20+I26+I34+I38+I63+I71+I77+I86+I91+I96+I99+I103+I105+I110+I112+I116+I122+I143+I145+I147+I149+I151+I153+I155 | D3: 평당 공사비 | E3: =B3/우리집!B8 | F3: 평형 / 등급요약 | G3: =우리집!B8&"평 / 바닥재 "&우리집!B64&" / 도배 "&우리집!B65&" / 주방 "&우리집!B69
A4: 부가세 별도/포함 토글 | B4: 별도 | C4: 별도/포함 | D4: 부가세율 | E4: 0.1 | F4: (10% 기본)
A5: 부가세 포함 총공사비 | B5: =IF(B4="포함",B3,B3*(1+E4)) | C5: 원 | D5: 평당(부가세 포함) | E5: =B5/우리집!B8 | F5: 원/평
A6: 시장 평당 적정 범위 | B6: =IF(우리집!$B$8<=30,IF(우리집!$B$61="가성비","100~150만/평",IF(우리집!$B$61="표준","180~220만/평","250~330만/평")),IF(우리집!$B$8<=40,IF(우리집!$B$61="가성비","90~140만/평",IF(우리집!$B$61="표준","160~200만/평","230~300만/평")),IF(우리집!$B$61="가성비","80~130만/평",IF(우리집!$B$61="표준","140~180만/평","210~280만/평")))) | D6: 평당 평가 | E6: =IF(우리집!$B$8<=30,IF(E3<800000,"⚠ 매우 낮음",IF(E3<=1500000,"✓ 가성비",IF(E3<=2200000,"✓ 표준",IF(E3<=3300000,"✓ 고급","✗ 상한 초과")))),IF(우리집!$B$8<=40,IF(E3<700000,"⚠ 매우 낮음",IF(E3<=1400000,"✓ 가성비",IF(E3<=2000000,"✓ 표준",IF(E3<=3000000,"✓ 고급","✗ 상한 초과")))),IF(E3<600000,"⚠ 매우 낮음",IF(E3<=1300000,"✓ 가성비",IF(E3<=1800000,"✓ 표준",IF(E3<=2800000,"✓ 고급","✗ 상한 초과"))))))
A8: # | B8: 공간 | C8: 공종 | D8: 단위 | E8: 수량 | F8: 등급 | G8: 추천 SKU | H8: 단가(원) | I8: 소계(원) | K8: 공종별 합계 | N8: 공간별 합계 | P8: category
A9: 1 | B9: 전체 | C9: 철거공사 | D9: =IFERROR(INDEX(자재마스터!$J:$J,MATCH("철거|"&우리집!$B$61,자재마스터!$AA:$AA,0)),"-") | E9: =우리집!$B$15 | F9: =우리집!$B$61 | G9: =IFERROR((INDEX(자재마스터!$F:$F, MATCH("철거|"&우리집!$B$61,자재마스터!$AA:$AA,0)) & " " & INDEX(자재마스터!$G:$G, MATCH("철거|"&우리집!$B$61,자재마스터!$AA:$AA,0))),"매칭없음") | H9: =IFERROR(INDEX(자재마스터!$M:$M,MATCH("철거|"&우리집!$B$61,자재마스터!$AA:$AA,0)),0) | I9: =IFERROR(E9*H9*IF(공사범위!$B$10="Y",1,0),0) | K9: 기본공사 | L9: =SUMIF($C$9:$C$112,"철거공사",$I$9:$I$112)+SUMIF($C$9:$C$112,"단열공사",$I$9:$I$112)+SUMIF($C$9:$C$112,"도장공사",$I$9:$I$112) | N9: 전체 | O9: =SUMIF($B$9:$B$112,"전체",$I$9:$I$112) | P9: =IFERROR(INDEX(자재마스터!$D:$D,MATCH("철거|"&우리집!$B$61,자재마스터!$AA:$AA,0)),"")
A10: 2 | B10: 전체 | C10: 단열공사 | D10: =IFERROR(INDEX(자재마스터!$J:$J,MATCH("insulation|"&우리집!$B$64,자재마스터!$Z:$Z,0)),"-") | E10: =우리집!$B$15 | F10: =우리집!$B$64 | G10: =IFERROR((INDEX(자재마스터!$F:$F, MATCH("insulation|"&우리집!$B$64,자재마스터!$Z:$Z,0)) & " " & INDEX(자재마스터!$G:$G, MATCH("insulation|"&우리집!$B$64,자재마스터!$Z:$Z,0))),"매칭없음") | H10: =IFERROR(INDEX(자재마스터!$M:$M,MATCH("insulation|"&우리집!$B$64,자재마스터!$Z:$Z,0)),0) | I10: =IFERROR(E10*H10*IF(공사범위!$B$11="Y",1,0),0) | K10: 샷시 교체 | L10: =SUMIF($C$9:$C$112,"샷시 교체",$I$9:$I$112) | N10: 거실 | O10: =SUMIF($B$9:$B$112,"거실",$I$9:$I$112) | P10: =IFERROR(INDEX(자재마스터!$D:$D,MATCH("insulation|"&우리집!$B$64,자재마스터!$Z:$Z,0)),"")
C11: ━ 기본공사 소계 | I11: =SUM(I9:I10) | K11: 바닥재 | L11: =SUMIF($C$9:$C$112,"바닥재",$I$9:$I$112) | N11: 주방 | O11: =SUMIF($B$9:$B$112,"주방",$I$9:$I$112)
A12: 3 | B12: 전체 | C12: (미사용) 샷시 — 공간별 통합 | D12: =IFERROR(INDEX(자재마스터!$J:$J,MATCH("window|"&우리집!$B$73,자재마스터!$Z:$Z,0)),"-") | E12: 0 | F12: =우리집!$B$73 | G12: =IFERROR((INDEX(자재마스터!$F:$F, MATCH("window|"&우리집!$B$73,자재마스터!$Z:$Z,0)) & " " & INDEX(자재마스터!$G:$G, MATCH("window|"&우리집!$B$73,자재마스터!$Z:$Z,0)))&" (비확장부)","매칭없음 (비확장부)") | H12: =IFERROR(INDEX(자재마스터!$M:$M,MATCH("window|"&우리집!$B$73,자재마스터!$Z:$Z,0)),0) | I12: =IFERROR(E12*H12*IF(공사범위!$B$22="Y",1,0),0) | K12: 도배 | L12: =SUMIF($C$9:$C$150,"도배",$I$9:$I$150)+SUMIF($C$9:$C$150,"가벽 도배 (양면)",$I$9:$I$150)+SUMIF($C$9:$C$160,"무문선 도배 추가비",$I$9:$I$160) | N12: 안방 | O12: =SUMIF($B$9:$B$112,"안방",$I$9:$I$112) | P12: =IFERROR(INDEX(자재마스터!$D:$D,MATCH("window|"&우리집!$B$73,자재마스터!$Z:$Z,0)),"")
A13: 4 | B13: 전체 | C13: 샷시 교체 | D13: =IFERROR(INDEX(자재마스터!$J:$J,MATCH("window|"&우리집!$B$73,자재마스터!$Z:$Z,0)),"-") | E13: =우리집!$B$16 * MIN(1, IFERROR(확장설정!$F$12/SUM(확장설정!$C$7:$C$11),0)) * IFERROR((IF(우리집!$J$22="Y",확장설정!$F$7,0)+IF(우리집!$J$23="Y",확장설정!$F$11,0)+IF(우리집!$J$24="Y",확장설정!$F$8,0)+IF(우리집!$J$25="Y",확장설정!$F$9,0)+IF(우리집!$J$26="Y",확장설정!$F$10,0))/확장설정!$F$12,0) | F13: =우리집!$B$73 | G13: =IFERROR((INDEX(자재마스터!$F:$F, MATCH("window|"&우리집!$B$73,자재마스터!$Z:$Z,0)) & " " & INDEX(자재마스터!$G:$G, MATCH("window|"&우리집!$B$73,자재마스터!$Z:$Z,0)))&" (확장부 자동)","매칭없음 (확장부)") | H13: =IFERROR(INDEX(자재마스터!$M:$M,MATCH("window|"&우리집!$B$73,자재마스터!$Z:$Z,0)),0) | I13: =IFERROR(E13*H13*IF(확장설정!$F$12>0,1,0),0) | K13: 몰딩 | L13: =SUMIF($C$9:$C$112,"몰딩",$I$9:$I$112) | N13: 작은방1 | O13: =SUMIF($B$9:$B$112,"작은방1",$I$9:$I$112) | P13: =IFERROR(INDEX(자재마스터!$D:$D,MATCH("window|"&우리집!$B$73,자재마스터!$Z:$Z,0)),"")
C14: ━ 샷시 소계 | I14: =SUM(I12:I13) | K14: 걸레받이 | L14: =SUMIF($C$9:$C$112,"걸레받이",$I$9:$I$112) | N14: 작은방2 | O14: =SUMIF($B$9:$B$112,"작은방2",$I$9:$I$112)
A15: 5 | B15: 거실 | C15: 바닥재 | D15: =IFERROR(INDEX(자재마스터!$J:$J,MATCH("flooring|"&우리집!$B$64,자재마스터!$Z:$Z,0)),"-") | E15: =(INDEX(표준면적!$B$3:$G$10,1,MATCH(표준면적!$J$2,표준면적!$B$2:$G$2,0))+(INDEX(표준면적!$B$3:$G$10,1,(MATCH(표준면적!$J$2,표준면적!$B$2:$G$2,0)+1))-INDEX(표준면적!$B$3:$G$10,1,MATCH(표준면적!$J$2,표준면적!$B$2:$G$2,0)))*표준면적!$J$4) | F15: =우리집!$B$64 | G15: =IFERROR((INDEX(자재마스터!$F:$F, MATCH("flooring|"&우리집!$B$64,자재마스터!$Z:$Z,0)) & " " & INDEX(자재마스터!$G:$G, MATCH("flooring|"&우리집!$B$64,자재마스터!$Z:$Z,0))),"매칭없음") | H15: =IFERROR(INDEX(자재마스터!$M:$M,MATCH("flooring|"&우리집!$B$64,자재마스터!$Z:$Z,0)),0) | I15: =IFERROR(E15*H15*IF(공사범위!$B$3="Y",1,0),0) | K15: 무걸레받이 추가비 | L15: =SUMIF($C$9:$C$112,"무걸레받이-목공추가비",$I$9:$I$112)+SUMIF($C$9:$C$112,"무걸레받이-도배추가비",$I$9:$I$112) | N15: 공용욕실 | O15: =SUMIF($B$9:$B$112,"공용욕실",$I$9:$I$112) | P15: =IFERROR(INDEX(자재마스터!$D:$D,MATCH("flooring|"&우리집!$B$64,자재마스터!$Z:$Z,0)),"")
A16: 6 | B16: 주방 | C16: 바닥재 | D16: =IFERROR(INDEX(자재마스터!$J:$J,MATCH("flooring|"&우리집!$B$64,자재마스터!$Z:$Z,0)),"-") | E16: =(INDEX(표준면적!$B$3:$G$10,2,MATCH(표준면적!$J$2,표준면적!$B$2:$G$2,0))+(INDEX(표준면적!$B$3:$G$10,2,(MATCH(표준면적!$J$2,표준면적!$B$2:$G$2,0)+1))-INDEX(표준면적!$B$3:$G$10,2,MATCH(표준면적!$J$2,표준면적!$B$2:$G$2,0)))*표준면적!$J$4) | F16: =우리집!$B$64 | G16: =IFERROR((INDEX(자재마스터!$F:$F, MATCH("flooring|"&우리집!$B$64,자재마스터!$Z:$Z,0)) & " " & INDEX(자재마스터!$G:$G, MATCH("flooring|"&우리집!$B$64,자재마스터!$Z:$Z,0))),"매칭없음") | H16: =IFERROR(INDEX(자재마스터!$M:$M,MATCH("flooring|"&우리집!$B$64,자재마스터!$Z:$Z,0)),0) | I16: =IFERROR(E16*H16*IF(공사범위!$B$4="Y",1,0),0) | K16: 무몰딩 추가비 | L16: =SUMIF($C$9:$C$112,"무몰딩-목공추가비",$I$9:$I$112)+SUMIF($C$9:$C$112,"무몰딩-도배인건비",$I$9:$I$112) | N16: 부부욕실 | O16: =SUMIF($B$9:$B$112,"부부욕실",$I$9:$I$112) | P16: =IFERROR(INDEX(자재마스터!$D:$D,MATCH("flooring|"&우리집!$B$64,자재마스터!$Z:$Z,0)),"")
A17: 7 | B17: 안방 | C17: 바닥재 | D17: =IFERROR(INDEX(자재마스터!$J:$J,MATCH("flooring|"&우리집!$B$64,자재마스터!$Z:$Z,0)),"-") | E17: =(INDEX(표준면적!$B$3:$G$10,3,MATCH(표준면적!$J$2,표준면적!$B$2:$G$2,0))+(INDEX(표준면적!$B$3:$G$10,3,(MATCH(표준면적!$J$2,표준면적!$B$2:$G$2,0)+1))-INDEX(표준면적!$B$3:$G$10,3,MATCH(표준면적!$J$2,표준면적!$B$2:$G$2,0)))*표준면적!$J$4) | F17: =우리집!$B$64 | G17: =IFERROR((INDEX(자재마스터!$F:$F, MATCH("flooring|"&우리집!$B$64,자재마스터!$Z:$Z,0)) & " " & INDEX(자재마스터!$G:$G, MATCH("flooring|"&우리집!$B$64,자재마스터!$Z:$Z,0))),"매칭없음") | H17: =IFERROR(INDEX(자재마스터!$M:$M,MATCH("flooring|"&우리집!$B$64,자재마스터!$Z:$Z,0)),0) | I17: =IFERROR(E17*H17*IF(공사범위!$B$5="Y",1,0),0) | K17: 욕실 컴포넌트 | L17: =SUMIF($C$9:$C$112,"젠다이",$I$9:$I$112)+SUMIF($C$9:$C$112,"방수",$I$9:$I$112)+SUMIF($C$9:$C$112,"타일자재",$I$9:$I$112)+SUMIF($C$9:$C$112,"타일시공",$I$9:$I$112)+SUMIF($C$9:$C$112,"파티션",$I$9:$I$112)+SUMIF($C$9:$C$112,"천정",$I$9:$I$112)+SUMIF($C$9:$C$112,"세면대",$I$9:$I$112)+SUMIF($C$9:$C$112,"수전",$I$9:$I$112)+SUMIF($C$9:$C$112,"양변기",$I$9:$I$112)+SUMIF($C$9:$C$112,"악세사리",$I$9:$I$112)+SUMIF($C$9:$C$112,"줄눈",$I$9:$I$112) | N17: 현관 | O17: =SUMIF($B$9:$B$112,"현관",$I$9:$I$112) | P17: =IFERROR(INDEX(자재마스터!$D:$D,MATCH("flooring|"&우리집!$B$64,자재마스터!$Z:$Z,0)),"")
A18: 8 | B18: 작은방1 | C18: 바닥재 | D18: =IFERROR(INDEX(자재마스터!$J:$J,MATCH("flooring|"&우리집!$B$64,자재마스터!$Z:$Z,0)),"-") | E18: =(INDEX(표준면적!$B$3:$G$10,4,MATCH(표준면적!$J$2,표준면적!$B$2:$G$2,0))+(INDEX(표준면적!$B$3:$G$10,4,(MATCH(표준면적!$J$2,표준면적!$B$2:$G$2,0)+1))-INDEX(표준면적!$B$3:$G$10,4,MATCH(표준면적!$J$2,표준면적!$B$2:$G$2,0)))*표준면적!$J$4) | F18: =우리집!$B$64 | G18: =IFERROR((INDEX(자재마스터!$F:$F, MATCH("flooring|"&우리집!$B$64,자재마스터!$Z:$Z,0)) & " " & INDEX(자재마스터!$G:$G, MATCH("flooring|"&우리집!$B$64,자재마스터!$Z:$Z,0))),"매칭없음") | H18: =IFERROR(INDEX(자재마스터!$M:$M,MATCH("flooring|"&우리집!$B$64,자재마스터!$Z:$Z,0)),0) | I18: =IFERROR(E18*H18*IF(공사범위!$B$6="Y",1,0),0) | K18: 욕실 설치비 | L18: =SUMIF($C$9:$C$112,"욕실 설치비",$I$9:$I$112) | N18: 합계 | O18: =SUM(O9:O17) | P18: =IFERROR(INDEX(자재마스터!$D:$D,MATCH("flooring|"&우리집!$B$64,자재마스터!$Z:$Z,0)),"")
A19: 9 | B19: 작은방2 | C19: 바닥재 | D19: =IFERROR(INDEX(자재마스터!$J:$J,MATCH("flooring|"&우리집!$B$64,자재마스터!$Z:$Z,0)),"-") | E19: =(INDEX(표준면적!$B$3:$G$10,5,MATCH(표준면적!$J$2,표준면적!$B$2:$G$2,0))+(INDEX(표준면적!$B$3:$G$10,5,(MATCH(표준면적!$J$2,표준면적!$B$2:$G$2,0)+1))-INDEX(표준면적!$B$3:$G$10,5,MATCH(표준면적!$J$2,표준면적!$B$2:$G$2,0)))*표준면적!$J$4) | F19: =우리집!$B$64 | G19: =IFERROR((INDEX(자재마스터!$F:$F, MATCH("flooring|"&우리집!$B$64,자재마스터!$Z:$Z,0)) & " " & INDEX(자재마스터!$G:$G, MATCH("flooring|"&우리집!$B$64,자재마스터!$Z:$Z,0))),"매칭없음") | H19: =IFERROR(INDEX(자재마스터!$M:$M,MATCH("flooring|"&우리집!$B$64,자재마스터!$Z:$Z,0)),0) | I19: =IFERROR(E19*H19*IF(공사범위!$B$7="Y",1,0),0) | K19: 타일 통합 시공 | L19: =SUMIF($C$9:$C$112,"타일 시공팀 (1팀×일)",$I$9:$I$112) | P19: =IFERROR(INDEX(자재마스터!$D:$D,MATCH("flooring|"&우리집!$B$64,자재마스터!$Z:$Z,0)),"")
C20: ━ 바닥재 소계 | I20: =SUM(I15:I19) | K20: 주방 컴포넌트 | L20: =SUMIF($C$9:$C$112,"몸체",$I$9:$I$112)+SUMIF($C$9:$C$112,"미드웨이",$I$9:$I$112)+SUMIF($C$9:$C$112,"도어",$I$9:$I$112)+SUMIF($C$9:$C$112,"상판",$I$9:$I$112)+SUMIF($C$9:$C$112,"하드웨어",$I$9:$I$112)+SUMIF($C$9:$C$112,"후드",$I$9:$I$112)+SUMIF($C$9:$C$112,"싱크볼",$I$9:$I$112)+SUMIF($C$9:$C$112,"주방가구 세트 (몸체+도어)",$I$9:$I$112)
A21: 10 | B21: 거실 | C21: 도배 | D21: =IFERROR(INDEX(자재마스터!$J:$J,MATCH("wallpaper|"&우리집!$B$65,자재마스터!$Z:$Z,0)),"-") | E21: =(INDEX(표준면적!$B$3:$G$10,1,MATCH(표준면적!$J$2,표준면적!$B$2:$G$2,0))+(INDEX(표준면적!$B$3:$G$10,1,(MATCH(표준면적!$J$2,표준면적!$B$2:$G$2,0)+1))-INDEX(표준면적!$B$3:$G$10,1,MATCH(표준면적!$J$2,표준면적!$B$2:$G$2,0)))*표준면적!$J$4)*2.8 | F21: =우리집!$B$65 | G21: =IFERROR((INDEX(자재마스터!$F:$F, MATCH("wallpaper|"&우리집!$B$65,자재마스터!$Z:$Z,0)) & " " & INDEX(자재마스터!$G:$G, MATCH("wallpaper|"&우리집!$B$65,자재마스터!$Z:$Z,0))),"매칭없음") | H21: =IFERROR(INDEX(자재마스터!$M:$M,MATCH("wallpaper|"&우리집!$B$65,자재마스터!$Z:$Z,0)),0) | I21: =IFERROR(E21*H21*IF(공사범위!$C$3="Y",1,0),0) | K21: 중문 | L21: =SUMIF($C$9:$C$112,"중문",$I$9:$I$112) | P21: =IFERROR(INDEX(자재마스터!$D:$D,MATCH("wallpaper|"&우리집!$B$65,자재마스터!$Z:$Z,0)),"")
A22: 11 | B22: 주방 | C22: 도배 | D22: =IFERROR(INDEX(자재마스터!$J:$J,MATCH("wallpaper|"&우리집!$B$65,자재마스터!$Z:$Z,0)),"-") | E22: =(INDEX(표준면적!$B$3:$G$10,2,MATCH(표준면적!$J$2,표준면적!$B$2:$G$2,0))+(INDEX(표준면적!$B$3:$G$10,2,(MATCH(표준면적!$J$2,표준면적!$B$2:$G$2,0)+1))-INDEX(표준면적!$B$3:$G$10,2,MATCH(표준면적!$J$2,표준면적!$B$2:$G$2,0)))*표준면적!$J$4)*2.8 | F22: =우리집!$B$65 | G22: =IFERROR((INDEX(자재마스터!$F:$F, MATCH("wallpaper|"&우리집!$B$65,자재마스터!$Z:$Z,0)) & " " & INDEX(자재마스터!$G:$G, MATCH("wallpaper|"&우리집!$B$65,자재마스터!$Z:$Z,0))),"매칭없음") | H22: =IFERROR(INDEX(자재마스터!$M:$M,MATCH("wallpaper|"&우리집!$B$65,자재마스터!$Z:$Z,0)),0) | I22: =IFERROR(E22*H22*IF(공사범위!$C$4="Y",1,0),0) | K22: 일반가구 | L22: =SUMIF($C$9:$C$112,"일반가구",$I$9:$I$112) | P22: =IFERROR(INDEX(자재마스터!$D:$D,MATCH("wallpaper|"&우리집!$B$65,자재마스터!$Z:$Z,0)),"")
A23: 12 | B23: 안방 | C23: 도배 | D23: =IFERROR(INDEX(자재마스터!$J:$J,MATCH("wallpaper|"&우리집!$B$65,자재마스터!$Z:$Z,0)),"-") | E23: =(INDEX(표준면적!$B$3:$G$10,3,MATCH(표준면적!$J$2,표준면적!$B$2:$G$2,0))+(INDEX(표준면적!$B$3:$G$10,3,(MATCH(표준면적!$J$2,표준면적!$B$2:$G$2,0)+1))-INDEX(표준면적!$B$3:$G$10,3,MATCH(표준면적!$J$2,표준면적!$B$2:$G$2,0)))*표준면적!$J$4)*2.8 | F23: =우리집!$B$65 | G23: =IFERROR((INDEX(자재마스터!$F:$F, MATCH("wallpaper|"&우리집!$B$65,자재마스터!$Z:$Z,0)) & " " & INDEX(자재마스터!$G:$G, MATCH("wallpaper|"&우리집!$B$65,자재마스터!$Z:$Z,0))),"매칭없음") | H23: =IFERROR(INDEX(자재마스터!$M:$M,MATCH("wallpaper|"&우리집!$B$65,자재마스터!$Z:$Z,0)),0) | I23: =IFERROR(E23*H23*IF(공사범위!$C$5="Y",1,0),0) | K23: 조명 | L23: =SUMIF($C$9:$C$112,"다운라이트",$I$9:$I$112)+SUMIF($C$9:$C$112,"거실 간접조명",$I$9:$I$112)+SUMIF($C$9:$C$112,"욕실 간접조명",$I$9:$I$112)+SUMIF($C$9:$C$112,"거실 마그네틱 라인",$I$9:$I$112)+SUMIF($C$9:$C$112,"주방 마그네틱 라인",$I$9:$I$112) | P23: =IFERROR(INDEX(자재마스터!$D:$D,MATCH("wallpaper|"&우리집!$B$65,자재마스터!$Z:$Z,0)),"")
A24: 13 | B24: 작은방1 | C24: 도배 | D24: =IFERROR(INDEX(자재마스터!$J:$J,MATCH("wallpaper|"&우리집!$B$65,자재마스터!$Z:$Z,0)),"-") | E24: =(INDEX(표준면적!$B$3:$G$10,4,MATCH(표준면적!$J$2,표준면적!$B$2:$G$2,0))+(INDEX(표준면적!$B$3:$G$10,4,(MATCH(표준면적!$J$2,표준면적!$B$2:$G$2,0)+1))-INDEX(표준면적!$B$3:$G$10,4,MATCH(표준면적!$J$2,표준면적!$B$2:$G$2,0)))*표준면적!$J$4)*2.8 | F24: =우리집!$B$65 | G24: =IFERROR((INDEX(자재마스터!$F:$F, MATCH("wallpaper|"&우리집!$B$65,자재마스터!$Z:$Z,0)) & " " & INDEX(자재마스터!$G:$G, MATCH("wallpaper|"&우리집!$B$65,자재마스터!$Z:$Z,0))),"매칭없음") | H24: =IFERROR(INDEX(자재마스터!$M:$M,MATCH("wallpaper|"&우리집!$B$65,자재마스터!$Z:$Z,0)),0) | I24: =IFERROR(E24*H24*IF(공사범위!$C$6="Y",1,0),0) | K24: 시스템에어컨 | L24: =SUMIF($C$9:$C$112,"시스템에어컨",$I$9:$I$112) | P24: =IFERROR(INDEX(자재마스터!$D:$D,MATCH("wallpaper|"&우리집!$B$65,자재마스터!$Z:$Z,0)),"")
A25: 14 | B25: 작은방2 | C25: 도배 | D25: =IFERROR(INDEX(자재마스터!$J:$J,MATCH("wallpaper|"&우리집!$B$65,자재마스터!$Z:$Z,0)),"-") | E25: =(INDEX(표준면적!$B$3:$G$10,5,MATCH(표준면적!$J$2,표준면적!$B$2:$G$2,0))+(INDEX(표준면적!$B$3:$G$10,5,(MATCH(표준면적!$J$2,표준면적!$B$2:$G$2,0)+1))-INDEX(표준면적!$B$3:$G$10,5,MATCH(표준면적!$J$2,표준면적!$B$2:$G$2,0)))*표준면적!$J$4)*2.8 | F25: =우리집!$B$65 | G25: =IFERROR((INDEX(자재마스터!$F:$F, MATCH("wallpaper|"&우리집!$B$65,자재마스터!$Z:$Z,0)) & " " & INDEX(자재마스터!$G:$G, MATCH("wallpaper|"&우리집!$B$65,자재마스터!$Z:$Z,0))),"매칭없음") | H25: =IFERROR(INDEX(자재마스터!$M:$M,MATCH("wallpaper|"&우리집!$B$65,자재마스터!$Z:$Z,0)),0) | I25: =IFERROR(E25*H25*IF(공사범위!$C$7="Y",1,0),0) | K25: 에어컨 실외기 | L25: =SUMIF($C$9:$C$112,"에어컨 실외기",$I$9:$I$112) | P25: =IFERROR(INDEX(자재마스터!$D:$D,MATCH("wallpaper|"&우리집!$B$65,자재마스터!$Z:$Z,0)),"")
C26: ━ 도배 소계 | I26: =SUM(I21:I25) | K26: 붙박이장 | L26: =SUMIF($C$9:$C$112,"붙박이장",$I$9:$I$112)
A27: 15 | B27: 거실 | C27: 몰딩 | D27: =IFERROR(INDEX(자재마스터!$J:$J,MATCH("molding|"&우리집!$B$66,자재마스터!$Z:$Z,0)),"-") | E27: =(INDEX(표준면적!$B$14:$G$21,1,MATCH(표준면적!$J$2,표준면적!$B$2:$G$2,0))+(INDEX(표준면적!$B$14:$G$21,1,(MATCH(표준면적!$J$2,표준면적!$B$2:$G$2,0)+1))-INDEX(표준면적!$B$14:$G$21,1,MATCH(표준면적!$J$2,표준면적!$B$2:$G$2,0)))*표준면적!$J$4) | F27: =우리집!$B$66 | G27: =IFERROR((INDEX(자재마스터!$F:$F, MATCH("molding|"&우리집!$B$66,자재마스터!$Z:$Z,0)) & " " & INDEX(자재마스터!$G:$G, MATCH("molding|"&우리집!$B$66,자재마스터!$Z:$Z,0))),"매칭없음") | H27: =IFERROR(INDEX(자재마스터!$M:$M,MATCH("molding|"&우리집!$B$66,자재마스터!$Z:$Z,0)),0) | I27: =IFERROR(E27*H27*IF(공사범위!$D$3="Y",1,0),0) | K27: 실링팬 | L27: =SUMIF($C$9:$C$112,"실링팬",$I$9:$I$112) | P27: =IFERROR(INDEX(자재마스터!$D:$D,MATCH("molding|"&우리집!$B$66,자재마스터!$Z:$Z,0)),"")
A28: 16 | B28: 주방 | C28: 몰딩 | D28: =IFERROR(INDEX(자재마스터!$J:$J,MATCH("molding|"&우리집!$B$66,자재마스터!$Z:$Z,0)),"-") | E28: =(INDEX(표준면적!$B$14:$G$21,2,MATCH(표준면적!$J$2,표준면적!$B$2:$G$2,0))+(INDEX(표준면적!$B$14:$G$21,2,(MATCH(표준면적!$J$2,표준면적!$B$2:$G$2,0)+1))-INDEX(표준면적!$B$14:$G$21,2,MATCH(표준면적!$J$2,표준면적!$B$2:$G$2,0)))*표준면적!$J$4) | F28: =우리집!$B$66 | G28: =IFERROR((INDEX(자재마스터!$F:$F, MATCH("molding|"&우리집!$B$66,자재마스터!$Z:$Z,0)) & " " & INDEX(자재마스터!$G:$G, MATCH("molding|"&우리집!$B$66,자재마스터!$Z:$Z,0))),"매칭없음") | H28: =IFERROR(INDEX(자재마스터!$M:$M,MATCH("molding|"&우리집!$B$66,자재마스터!$Z:$Z,0)),0) | I28: =IFERROR(E28*H28*IF(공사범위!$D$4="Y",1,0),0) | K28: 목공사 | L28: =SUMIF($C$9:$C$112,"목공사 기본",$I$9:$I$112)+SUMIF($C$9:$C$112,"천정 우물→평천정",$I$9:$I$112)+SUMIF($C$9:$C$112,"가벽/구조 변경",$I$9:$I$112)+SUMIF($C$9:$C$160,"무문선 목공 추가비",$I$9:$I$160) | P28: =IFERROR(INDEX(자재마스터!$D:$D,MATCH("molding|"&우리집!$B$66,자재마스터!$Z:$Z,0)),"")
A29: 17 | B29: 안방 | C29: 몰딩 | D29: =IFERROR(INDEX(자재마스터!$J:$J,MATCH("molding|"&우리집!$B$66,자재마스터!$Z:$Z,0)),"-") | E29: =(INDEX(표준면적!$B$14:$G$29,3,MATCH(표준면적!$J$2,표준면적!$B$2:$G$2,0))+(INDEX(표준면적!$B$14:$G$29,3,(MATCH(표준면적!$J$2,표준면적!$B$2:$G$2,0)+1))-INDEX(표준면적!$B$14:$G$29,3,MATCH(표준면적!$J$2,표준면적!$B$2:$G$2,0)))*표준면적!$J$4) | F29: =우리집!$B$66 | G29: =IFERROR((INDEX(자재마스터!$F:$F, MATCH("molding|"&우리집!$B$66,자재마스터!$Z:$Z,0)) & " " & INDEX(자재마스터!$G:$G, MATCH("molding|"&우리집!$B$66,자재마스터!$Z:$Z,0))),"매칭없음") | H29: =IFERROR(INDEX(자재마스터!$M:$M,MATCH("molding|"&우리집!$B$66,자재마스터!$Z:$Z,0)),0) | I29: =IFERROR(E29*H29*IF(공사범위!$D$5="Y",1,0),0) | K29: 확장공사 | L29: =SUMIF($C$9:$C$112,"확장공사",$I$9:$I$112) | P29: =IFERROR(INDEX(자재마스터!$D:$D,MATCH("molding|"&우리집!$B$66,자재마스터!$Z:$Z,0)),"")
A30: 18 | B30: 작은방1 | C30: 몰딩 | D30: =IFERROR(INDEX(자재마스터!$J:$J,MATCH("molding|"&우리집!$B$66,자재마스터!$Z:$Z,0)),"-") | E30: =(INDEX(표준면적!$B$14:$G$21,4,MATCH(표준면적!$J$2,표준면적!$B$2:$G$2,0))+(INDEX(표준면적!$B$14:$G$21,4,(MATCH(표준면적!$J$2,표준면적!$B$2:$G$2,0)+1))-INDEX(표준면적!$B$14:$G$21,4,MATCH(표준면적!$J$2,표준면적!$B$2:$G$2,0)))*표준면적!$J$4) | F30: =우리집!$B$66 | G30: =IFERROR((INDEX(자재마스터!$F:$F, MATCH("molding|"&우리집!$B$66,자재마스터!$Z:$Z,0)) & " " & INDEX(자재마스터!$G:$G, MATCH("molding|"&우리집!$B$66,자재마스터!$Z:$Z,0))),"매칭없음") | H30: =IFERROR(INDEX(자재마스터!$M:$M,MATCH("molding|"&우리집!$B$66,자재마스터!$Z:$Z,0)),0) | I30: =IFERROR(E30*H30*IF(공사범위!$D$6="Y",1,0),0) | K30: 스위치/콘센트 | L30: =SUMIF($C$9:$C$120,"스위치/콘센트",$I$9:$I$120) | P30: =IFERROR(INDEX(자재마스터!$D:$D,MATCH("molding|"&우리집!$B$66,자재마스터!$Z:$Z,0)),"")
A31: 19 | B31: 작은방2 | C31: 몰딩 | D31: =IFERROR(INDEX(자재마스터!$J:$J,MATCH("molding|"&우리집!$B$66,자재마스터!$Z:$Z,0)),"-") | E31: =(INDEX(표준면적!$B$14:$G$21,5,MATCH(표준면적!$J$2,표준면적!$B$2:$G$2,0))+(INDEX(표준면적!$B$14:$G$21,5,(MATCH(표준면적!$J$2,표준면적!$B$2:$G$2,0)+1))-INDEX(표준면적!$B$14:$G$21,5,MATCH(표준면적!$J$2,표준면적!$B$2:$G$2,0)))*표준면적!$J$4) | F31: =우리집!$B$66 | G31: =IFERROR((INDEX(자재마스터!$F:$F, MATCH("molding|"&우리집!$B$66,자재마스터!$Z:$Z,0)) & " " & INDEX(자재마스터!$G:$G, MATCH("molding|"&우리집!$B$66,자재마스터!$Z:$Z,0))),"매칭없음") | H31: =IFERROR(INDEX(자재마스터!$M:$M,MATCH("molding|"&우리집!$B$66,자재마스터!$Z:$Z,0)),0) | I31: =IFERROR(E31*H31*IF(공사범위!$D$7="Y",1,0),0) | K31: 인덕션 전용선 | L31: =SUMIF($C$9:$C$120,"인덕션 전용선",$I$9:$I$120) | P31: =IFERROR(INDEX(자재마스터!$D:$D,MATCH("molding|"&우리집!$B$66,자재마스터!$Z:$Z,0)),"")
A32: 20 | B32: 전체 | C32: 무몰딩-목공추가비 | D32: =IFERROR(INDEX(자재마스터!$J:$J,MATCH("molding_carpentry|"&우리집!$B$66,자재마스터!$Z:$Z,0)),"-") | E32: =우리집!$B$14*COUNTIF(우리집!$F$22,"N")/5 | F32: =우리집!$B$66 | G32: =IFERROR((INDEX(자재마스터!$F:$F, MATCH("molding_carpentry|"&우리집!$B$66,자재마스터!$Z:$Z,0)) & " " & INDEX(자재마스터!$G:$G, MATCH("molding_carpentry|"&우리집!$B$66,자재마스터!$Z:$Z,0))),"매칭없음") | H32: =IFERROR(INDEX(자재마스터!$M:$M,MATCH("molding_carpentry|"&우리집!$B$66,자재마스터!$Z:$Z,0)),0) | I32: =IFERROR(E32*H32,0) | K32: 발코니/다용도실 | L32: =SUMIF($C$9:$C$120,"발코니 바닥타일",$I$9:$I$120)+SUMIF($C$9:$C$120,"다용도실 바닥타일",$I$9:$I$120)+SUMIF($C$9:$C$120,"발코니 도장",$I$9:$I$120)+SUMIF($C$9:$C$120,"다용도실 도장",$I$9:$I$120) | P32: =IFERROR(INDEX(자재마스터!$D:$D,MATCH("molding_carpentry|"&우리집!$B$66,자재마스터!$Z:$Z,0)),"")
A33: 21 | B33: 전체 | C33: 무몰딩-도배인건비 | D33: =IFERROR(INDEX(자재마스터!$J:$J,MATCH("molding_wallpaper|"&우리집!$B$66,자재마스터!$Z:$Z,0)),"-") | E33: =우리집!$B$14*COUNTIF(우리집!$F$22,"N")/5 | F33: =우리집!$B$66 | G33: =IFERROR((INDEX(자재마스터!$F:$F, MATCH("molding_wallpaper|"&우리집!$B$66,자재마스터!$Z:$Z,0)) & " " & INDEX(자재마스터!$G:$G, MATCH("molding_wallpaper|"&우리집!$B$66,자재마스터!$Z:$Z,0))),"매칭없음") | H33: =IFERROR(INDEX(자재마스터!$M:$M,MATCH("molding_wallpaper|"&우리집!$B$66,자재마스터!$Z:$Z,0)),0) | I33: =IFERROR(E33*H33,0) | K33: 합계 | L33: =SUM(L9:L32)+SUM(L34:L45) | P33: =IFERROR(INDEX(자재마스터!$D:$D,MATCH("molding_wallpaper|"&우리집!$B$66,자재마스터!$Z:$Z,0)),"")
C34: ━ 몰딩 소계 | I34: =SUM(I27:I33) | K34: 전기 기본공사 | L34: =SUMIF($C$9:$C$120,"전기 기본공사",$I$9:$I$120)
A35: 22 | B35: 전체 | C35: 걸레받이 | D35: =IFERROR(INDEX(자재마스터!$J:$J,MATCH("baseboard|"&우리집!$B$80,자재마스터!$Z:$Z,0)),"-") | E35: =우리집!$B$14*COUNTIF(우리집!$F$22,"Y")/5 | F35: =우리집!$B$80 | G35: =IFERROR((INDEX(자재마스터!$F:$F, MATCH("baseboard|"&우리집!$B$80,자재마스터!$Z:$Z,0)) & " " & INDEX(자재마스터!$G:$G, MATCH("baseboard|"&우리집!$B$80,자재마스터!$Z:$Z,0))),"매칭없음") | H35: =IFERROR(INDEX(자재마스터!$M:$M,MATCH("baseboard|"&우리집!$B$80,자재마스터!$Z:$Z,0)),0) | I35: =IFERROR(E35*H35,0) | K35: 설비 기본공사 | L35: =SUMIF($C$9:$C$120,"설비 기본공사",$I$9:$I$120) | P35: =IFERROR(INDEX(자재마스터!$D:$D,MATCH("baseboard|"&우리집!$B$80,자재마스터!$Z:$Z,0)),"")
A36: 23 | B36: 전체 | C36: 무걸레받이-목공추가비 | D36: =IFERROR(INDEX(자재마스터!$J:$J,MATCH("baseboard_carpentry|"&우리집!$B$80,자재마스터!$Z:$Z,0)),"-") | E36: =우리집!$B$14*COUNTIF(우리집!$F$22,"N")/5 | F36: =우리집!$B$80 | G36: =IFERROR((INDEX(자재마스터!$F:$F, MATCH("baseboard_carpentry|"&우리집!$B$80,자재마스터!$Z:$Z,0)) & " " & INDEX(자재마스터!$G:$G, MATCH("baseboard_carpentry|"&우리집!$B$80,자재마스터!$Z:$Z,0))),"매칭없음") | H36: =IFERROR(INDEX(자재마스터!$M:$M,MATCH("baseboard_carpentry|"&우리집!$B$80,자재마스터!$Z:$Z,0)),0) | I36: =IFERROR(E36*H36,0) | K36: 난방온도조절기 | L36: =SUMIF($C$9:$C$120,"난방온도조절기",$I$9:$I$120) | P36: =IFERROR(INDEX(자재마스터!$D:$D,MATCH("baseboard_carpentry|"&우리집!$B$80,자재마스터!$Z:$Z,0)),"")
A37: 24 | B37: 전체 | C37: 무걸레받이-도배추가비 (무몰딩과 통합) | D37: =IFERROR(INDEX(자재마스터!$J:$J,MATCH("baseboard_wallpaper|"&우리집!$B$80,자재마스터!$Z:$Z,0)),"-") | E37: =우리집!$B$14*COUNTIF(우리집!$F$22,"N")/5*0 | F37: =우리집!$B$80 | G37: =IFERROR((INDEX(자재마스터!$F:$F, MATCH("baseboard_wallpaper|"&우리집!$B$80,자재마스터!$Z:$Z,0)) & " " & INDEX(자재마스터!$G:$G, MATCH("baseboard_wallpaper|"&우리집!$B$80,자재마스터!$Z:$Z,0))),"매칭없음") | H37: =IFERROR(INDEX(자재마스터!$M:$M,MATCH("baseboard_wallpaper|"&우리집!$B$80,자재마스터!$Z:$Z,0)),0) | I37: =IFERROR(E37*H37,0) | K37: 구청 신고 | L37: =SUMIF($C$9:$C$120,"구청 확장공사 신고",$I$9:$I$120) | P37: =IFERROR(INDEX(자재마스터!$D:$D,MATCH("baseboard_wallpaper|"&우리집!$B$80,자재마스터!$Z:$Z,0)),"")
C38: ━ 걸레받이 소계 | I38: =SUM(I35:I37) | K38: 실리콘 인건비 | L38: =SUMIF($C$9:$C$120,"실리콘 - 인건비",$I$9:$I$120)
A39: 25 | B39: 공용욕실 | C39: 젠다이 | D39: =IFERROR(INDEX(자재마스터!$J:$J,MATCH("bath_jendai|"&IF(욕실설정!$B$4="기본",우리집!$B$67,욕실설정!$B$4),자재마스터!$Z:$Z,0)),"-") | E39: =우리집!$B$11 | F39: =IF(욕실설정!$B$4="기본",우리집!$B$67,욕실설정!$B$4) | G39: =IFERROR((INDEX(자재마스터!$F:$F, MATCH("bath_jendai|"&IF(욕실설정!$B$4="기본",우리집!$B$67,욕실설정!$B$4),자재마스터!$Z:$Z,0)) & " " & INDEX(자재마스터!$G:$G, MATCH("bath_jendai|"&IF(욕실설정!$B$4="기본",우리집!$B$67,욕실설정!$B$4),자재마스터!$Z:$Z,0))),"매칭없음") | H39: =IFERROR(INDEX(자재마스터!$M:$M,MATCH("bath_jendai|"&IF(욕실설정!$B$4="기본",우리집!$B$67,욕실설정!$B$4),자재마스터!$Z:$Z,0)),0) | I39: =IFERROR(E39*H39*IF(욕실설정!$D$4="Y",1,0),0) | K39: 실리콘 욕실주방 | L39: =SUMIF($C$9:$C$120,"실리콘 - 자재 (욕실·주방)",$I$9:$I$120) | P39: =IFERROR(INDEX(자재마스터!$D:$D,MATCH("bath_jendai|"&IF(욕실설정!$B$4="기본",우리집!$B$67,욕실설정!$B$4),자재마스터!$Z:$Z,0)),"")
A40: 26 | B40: 공용욕실 | C40: 방수 | D40: =IFERROR(INDEX(자재마스터!$J:$J,MATCH("bath_waterproof|"&IF(욕실설정!$B$5="기본",우리집!$B$67,욕실설정!$B$5),자재마스터!$Z:$Z,0)),"-") | E40: =((INDEX(표준면적!$B$3:$G$10,6,MATCH(표준면적!$J$2,표준면적!$B$2:$G$2,0))+(INDEX(표준면적!$B$3:$G$10,6,(MATCH(표준면적!$J$2,표준면적!$B$2:$G$2,0)+1))-INDEX(표준면적!$B$3:$G$10,6,MATCH(표준면적!$J$2,표준면적!$B$2:$G$2,0)))*표준면적!$J$4)+(INDEX(표준면적!$B$14:$G$21,6,MATCH(표준면적!$J$2,표준면적!$B$2:$G$2,0))+(INDEX(표준면적!$B$14:$G$21,6,(MATCH(표준면적!$J$2,표준면적!$B$2:$G$2,0)+1))-INDEX(표준면적!$B$14:$G$21,6,MATCH(표준면적!$J$2,표준면적!$B$2:$G$2,0)))*표준면적!$J$4))*우리집!$B$11 | F40: =IF(욕실설정!$B$5="기본",우리집!$B$67,욕실설정!$B$5) | G40: =IFERROR((INDEX(자재마스터!$F:$F, MATCH("bath_waterproof|"&IF(욕실설정!$B$5="기본",우리집!$B$67,욕실설정!$B$5),자재마스터!$Z:$Z,0)) & " " & INDEX(자재마스터!$G:$G, MATCH("bath_waterproof|"&IF(욕실설정!$B$5="기본",우리집!$B$67,욕실설정!$B$5),자재마스터!$Z:$Z,0))),"매칭없음") | H40: =IFERROR(INDEX(자재마스터!$M:$M,MATCH("bath_waterproof|"&IF(욕실설정!$B$5="기본",우리집!$B$67,욕실설정!$B$5),자재마스터!$Z:$Z,0)),0) | I40: =IFERROR(E40*H40*IF(욕실설정!$D$5="Y",1,0),0) | K40: 실리콘 외기새시 | L40: =SUMIF($C$9:$C$120,"실리콘 - 자재 (외기·새시)",$I$9:$I$120) | P40: =IFERROR(INDEX(자재마스터!$D:$D,MATCH("bath_waterproof|"&IF(욕실설정!$B$5="기본",우리집!$B$67,욕실설정!$B$5),자재마스터!$Z:$Z,0)),"")
A41: 27 | B41: 공용욕실 | C41: 타일자재 | D41: =IFERROR(INDEX(자재마스터!$J:$J,MATCH("bath_tile|"&IF(욕실설정!$B$6="기본",우리집!$B$67,욕실설정!$B$6),자재마스터!$Z:$Z,0)),"-") | E41: =((INDEX(표준면적!$B$3:$G$10,6,MATCH(표준면적!$J$2,표준면적!$B$2:$G$2,0))+(INDEX(표준면적!$B$3:$G$10,6,(MATCH(표준면적!$J$2,표준면적!$B$2:$G$2,0)+1))-INDEX(표준면적!$B$3:$G$10,6,MATCH(표준면적!$J$2,표준면적!$B$2:$G$2,0)))*표준면적!$J$4)+(INDEX(표준면적!$B$14:$G$21,6,MATCH(표준면적!$J$2,표준면적!$B$2:$G$2,0))+(INDEX(표준면적!$B$14:$G$21,6,(MATCH(표준면적!$J$2,표준면적!$B$2:$G$2,0)+1))-INDEX(표준면적!$B$14:$G$21,6,MATCH(표준면적!$J$2,표준면적!$B$2:$G$2,0)))*표준면적!$J$4)*2.4)*우리집!$B$11 | F41: =IF(욕실설정!$B$6="기본",우리집!$B$67,욕실설정!$B$6) | G41: =IFERROR((INDEX(자재마스터!$F:$F, MATCH("bath_tile|"&IF(욕실설정!$B$6="기본",우리집!$B$67,욕실설정!$B$6),자재마스터!$Z:$Z,0)) & " " & INDEX(자재마스터!$G:$G, MATCH("bath_tile|"&IF(욕실설정!$B$6="기본",우리집!$B$67,욕실설정!$B$6),자재마스터!$Z:$Z,0))),"매칭없음") | H41: =IFERROR(INDEX(자재마스터!$M:$M,MATCH("bath_tile|"&IF(욕실설정!$B$6="기본",우리집!$B$67,욕실설정!$B$6),자재마스터!$Z:$Z,0)),0) | I41: =IFERROR(E41*H41*IF(욕실설정!$D$6="Y",1,0),0) | K41: 공간별 샷시 교체 | L41: =SUMIF($C$9:$C$130,"샷시 교체 (공간별)",$I$9:$I$130) | P41: =IFERROR(INDEX(자재마스터!$D:$D,MATCH("bath_tile|"&IF(욕실설정!$B$6="기본",우리집!$B$67,욕실설정!$B$6),자재마스터!$Z:$Z,0)),"")
A42: 28 | B42: 공용욕실 | C42: 타일시공 | D42: =IFERROR(INDEX(자재마스터!$J:$J,MATCH("bath_tile_method|"&IF(욕실설정!$B$7="기본",우리집!$B$67,욕실설정!$B$7),자재마스터!$Z:$Z,0)),"-") | E42: =(INDEX(표준면적!$B$14:$G$21,6,MATCH(표준면적!$J$2,표준면적!$B$2:$G$2,0))+(INDEX(표준면적!$B$14:$G$21,6,(MATCH(표준면적!$J$2,표준면적!$B$2:$G$2,0)+1))-INDEX(표준면적!$B$14:$G$21,6,MATCH(표준면적!$J$2,표준면적!$B$2:$G$2,0)))*표준면적!$J$4)*우리집!$B$11 | F42: =IF(욕실설정!$B$7="기본",우리집!$B$67,욕실설정!$B$7) | G42: =IFERROR((INDEX(자재마스터!$F:$F, MATCH("bath_tile_method|"&IF(욕실설정!$B$7="기본",우리집!$B$67,욕실설정!$B$7),자재마스터!$Z:$Z,0)) & " " & INDEX(자재마스터!$G:$G, MATCH("bath_tile_method|"&IF(욕실설정!$B$7="기본",우리집!$B$67,욕실설정!$B$7),자재마스터!$Z:$Z,0))),"매칭없음") | H42: =IFERROR(INDEX(자재마스터!$M:$M,MATCH("bath_tile_method|"&IF(욕실설정!$B$7="기본",우리집!$B$67,욕실설정!$B$7),자재마스터!$Z:$Z,0)),0) | I42: =IFERROR(E42*H42*IF(욕실설정!$D$7="Y",1,0),0) | K42: 기타 공종 추가 | L42: =SUMIF($C$9:$C$150,"엘리베이터 보양",$I$9:$I$150)+SUMIF($C$9:$C$150,"주민 동의서 징구",$I$9:$I$150)+SUMIF($C$9:$C$150,"준공청소",$I$9:$I$150) | P42: =IFERROR(INDEX(자재마스터!$D:$D,MATCH("bath_tile_method|"&IF(욕실설정!$B$7="기본",우리집!$B$67,욕실설정!$B$7),자재마스터!$Z:$Z,0)),"")
...

Sheet 자재마스터
A1: material_id | B1: status | C1: work_type | D1: category | E1: sub_category | F1: brand | G1: product_line | H1: installer_spec | I1: tags | J1: unit_type | K1: material_price | L1: labor_price | M1: total_unit_price | N1: price_source | O1: price_updated_at | P1: verified_by | Q1: image_main_url | R1: image_case1_url | S1: image_case2_url | T1: image_alt_text | U1: image_source | V1: image_license_note | W1: image_updated_at | X1: notes_internal | Y1: primary_grade | Z1: lookup_key | AA1: secondary_key
A2: MAT-FL-001 | B2: active | C2: flooring | D2: 마루 | E2: 강마루 | F2: 구정마루 | G2: 구정강 | H2: 구정마루 구정강 9.4×800×7.5T | I2: 가성비, 주력 | J2: per_m2 | K2: 22000 | L2: 12000 | M2: =K2+L2 | N2: 시장가 추정 | O2: 2026-04 | P2: operator | Y2: =LEFT(I2,FIND(",",I2&",")-1) | Z2: =C2&"|"&Y2 | AA2: =E2&"|"&Y2
A3: MAT-FL-002 | B3: active | C3: flooring | D3: 마루 | E3: 장판 | F3: LX하우시스 | G3: 지인 | H3: LX 지인 8.0T | I3: 가성비 | J3: per_m2 | K3: 12000 | L3: 12000 | M3: =K3+L3 | N3: 시장가 추정 | O3: 2026-04 | P3: operator | Y3: =LEFT(I3,FIND(",",I3&",")-1) | Z3: =C3&"|"&Y3 | AA3: =E3&"|"&Y3
A4: MAT-FL-003 | B4: active | C4: flooring | D4: 마루 | E4: 장판 | F4: 한화L&C | G4: 한샘프리미엄 | H4: 한화L&C 한샘프리미엄 8.0T | I4: 가성비 | J4: per_m2 | K4: 15000 | L4: 12000 | M4: =K4+L4 | N4: 시장가 추정 | O4: 2026-04 | P4: operator | Y4: =LEFT(I4,FIND(",",I4&",")-1) | Z4: =C4&"|"&Y4 | AA4: =E4&"|"&Y4
A5: MAT-FL-004 | B5: active | C5: flooring | D5: 마루 | E5: 강화마루 | F5: 동화자연마루 | G5: 나투스진 | H5: 동화자연마루 나투스진 8.0T | I5: 가성비 | J5: per_m2 | K5: 22000 | L5: 13000 | M5: =K5+L5 | N5: 시장가 추정 | O5: 2026-04 | P5: operator | Y5: =LEFT(I5,FIND(",",I5&",")-1) | Z5: =C5&"|"&Y5 | AA5: =E5&"|"&Y5
A6: MAT-FL-005 | B6: active | C6: flooring | D6: 마루 | E6: 강마루 | F6: 구정마루 | G6: 그랜드텍스처165 | H6: 구정마루 그랜드텍스처 165 165×1200×7.5T | I6: 표준, 주력 | J6: per_m2 | K6: 32000 | L6: 14000 | M6: =K6+L6 | N6: 시장가 추정 | O6: 2026-04 | P6: operator | Y6: =LEFT(I6,FIND(",",I6&",")-1) | Z6: =C6&"|"&Y6 | AA6: =E6&"|"&Y6
A7: MAT-FL-006 | B7: active | C7: flooring | D7: 마루 | E7: 장판 | F7: 녹수 | G7: 펠리체 | H7: 녹수 펠리체 9.0T | I7: 표준 | J7: per_m2 | K7: 22000 | L7: 14000 | M7: =K7+L7 | N7: 시장가 추정 | O7: 2026-04 | P7: operator | Y7: =LEFT(I7,FIND(",",I7&",")-1) | Z7: =C7&"|"&Y7 | AA7: =E7&"|"&Y7
A8: MAT-FL-007 | B8: active | C8: flooring | D8: 마루 | E8: 강화마루 | F8: 구정마루 | G8: 강화시리즈 | H8: 구정마루 강화 12T | I8: 표준 | J8: per_m2 | K8: 28000 | L8: 14000 | M8: =K8+L8 | N8: 시장가 추정 | O8: 2026-04 | P8: operator | Y8: =LEFT(I8,FIND(",",I8&",")-1) | Z8: =C8&"|"&Y8 | AA8: =E8&"|"&Y8
A9: MAT-FL-008 | B9: active | C9: flooring | D9: 마루 | E9: 강화마루 | F9: LX하우시스 | G9: 헤링본 | H9: LX하우시스 강화 헤링본 | I9: 표준 | J9: per_m2 | K9: 35000 | L9: 20000 | M9: =K9+L9 | N9: 시장 시세 검증 (2026-05) | O9: 2026-05 | P9: operator | X9: 쓰레드/SNS 시장가 검증 (헤링본 추가비 +5,000/㎡) | Y9: =LEFT(I9,FIND(",",I9&",")-1) | Z9: =C9&"|"&Y9 | AA9: =E9&"|"&Y9
A10: MAT-FL-009 | B10: active | C10: flooring | D10: 마루 | E10: 강마루 | F10: 동화자연마루 | G10: 더원 | H10: 동화자연마루 더원 165×1200×7.5T | I10: 표준 | J10: per_m2 | K10: 40000 | L10: 16000 | M10: =K10+L10 | N10: 시장가 추정 | O10: 2026-04 | P10: operator | Y10: =LEFT(I10,FIND(",",I10&",")-1) | Z10: =C10&"|"&Y10 | AA10: =E10&"|"&Y10
A11: MAT-FL-010 | B11: active | C11: flooring | D11: 마루 | E11: 강마루 | F11: LX하우시스 | G11: 에디톤180 | H11: LX하우시스 에디톤 180×1220×5.0T | I11: 고급, 주력 | J11: per_m2 | K11: 55000 | L11: 22000 | M11: =K11+L11 | N11: 시장가 추정 | O11: 2026-04 | P11: operator | Y11: =LEFT(I11,FIND(",",I11&",")-1) | Z11: =C11&"|"&Y11 | AA11: =E11&"|"&Y11
A12: MAT-FL-011 | B12: active | C12: flooring | D12: 마루 | E12: 강마루 | F12: 구정마루 | G12: 헤링본 | H12: 구정마루 헤링본 9.4×600×7.5T | I12: 고급 | J12: per_m2 | K12: 50000 | L12: 26000 | M12: =K12+L12 | N12: 시장 시세 검증 (2026-05) | O12: 2026-05 | P12: operator | X12: 쓰레드/SNS (헤링본 추가 인건비) | Y12: =LEFT(I12,FIND(",",I12&",")-1) | Z12: =C12&"|"&Y12 | AA12: =E12&"|"&Y12
A13: MAT-FL-012 | B13: active | C13: flooring | D13: 마루 | E13: 원목마루 | F13: 이건마루 | G13: 골드 | H13: 이건마루 골드 14×120×900 | I13: 고급 | J13: per_m2 | K13: 65000 | L13: 26000 | M13: =K13+L13 | N13: 시장가 추정 | O13: 2026-04 | P13: operator | Y13: =LEFT(I13,FIND(",",I13&",")-1) | Z13: =C13&"|"&Y13 | AA13: =E13&"|"&Y13
A14: MAT-FL-013 | B14: active | C14: flooring | D14: 마루 | E14: 원목마루 | F14: 구정마루 | G14: 원목광폭 | H14: 구정마루 원목 200폭 | I14: 고급 | J14: per_m2 | K14: 78000 | L14: 30000 | M14: =K14+L14 | N14: 시장가 추정 | O14: 2026-04 | P14: operator | Y14: =LEFT(I14,FIND(",",I14&",")-1) | Z14: =C14&"|"&Y14 | AA14: =E14&"|"&Y14
A15: MAT-WP-001 | B15: active | C15: wallpaper | D15: 도배 | E15: 합지 | F15: 개나리벽지 | G15: 광폭합지 | H15: 개나리벽지 광폭합지 | I15: 가성비, 주력 | J15: per_m2 | K15: 3500 | L15: 4200 | M15: =K15+L15 | N15: 시장 시세 검증 (2026-05) | O15: 2026-05 | P15: operator | X15: 셀인카페·숨고 (광폭 합지 부자재포함) | Y15: =LEFT(I15,FIND(",",I15&",")-1) | Z15: =C15&"|"&Y15 | AA15: =E15&"|"&Y15
A16: MAT-WP-002 | B16: active | C16: wallpaper | D16: 도배 | E16: 합지 | F16: 개나리벽지 | G16: 일반합지 | H16: 개나리벽지 일반합지 | I16: 가성비 | J16: per_m2 | K16: 3000 | L16: 4500 | M16: =K16+L16 | N16: 시장 시세 검증 (2026-05) | O16: 2026-05 | P16: operator | X16: 셀인카페·숨고 (합지 자재 5,000~7,000/㎡) | 셀인카페·숨고 (합지 인건비 4,000~6,000/㎡) | Y16: =LEFT(I16,FIND(",",I16&",")-1) | Z16: =C16&"|"&Y16 | AA16: =E16&"|"&Y16
A17: MAT-WP-003 | B17: active | C17: wallpaper | D17: 도배 | E17: 수성도장 | F17: 삼화페인트 | G17: 수성페인트 | H17: 수성페인트 일반급 2회 | I17: 가성비 | J17: per_m2 | K17: 3500 | L17: 5000 | M17: =K17+L17 | N17: 시장가 추정 | O17: 2026-04 | P17: operator | Y17: =LEFT(I17,FIND(",",I17&",")-1) | Z17: =C17&"|"&Y17 | AA17: =E17&"|"&Y17
A18: MAT-WP-004 | B18: active | C18: wallpaper | D18: 도배 | E18: 실크 | F18: LX하우시스 | G18: 베스띠 | H18: LX하우시스 베스띠 | I18: 표준, 주력 | J18: per_m2 | K18: 7000 | L18: 5500 | M18: =K18+L18 | N18: 시장가 추정 | O18: 2026-04 | P18: operator | Y18: =LEFT(I18,FIND(",",I18&",")-1) | Z18: =C18&"|"&Y18 | AA18: =E18&"|"&Y18
A19: MAT-WP-005 | B19: active | C19: wallpaper | D19: 도배 | E19: 합지 | F19: LX하우시스 | G19: 친환경합지 | H19: LX하우시스 친환경합지 | I19: 표준 | J19: per_m2 | K19: 4000 | L19: 4500 | M19: =K19+L19 | N19: 시장가 추정 | O19: 2026-04 | P19: operator | Y19: =LEFT(I19,FIND(",",I19&",")-1) | Z19: =C19&"|"&Y19 | AA19: =E19&"|"&Y19
A20: MAT-WP-006 | B20: active | C20: wallpaper | D20: 도배 | E20: 실크 | F20: LX하우시스 | G20: 베스띠광폭 | H20: LX하우시스 베스띠 광폭 | I20: 표준 | J20: per_m2 | K20: 8500 | L20: 6000 | M20: =K20+L20 | N20: 시장가 추정 | O20: 2026-04 | P20: operator | Y20: =LEFT(I20,FIND(",",I20&",")-1) | Z20: =C20&"|"&Y20 | AA20: =E20&"|"&Y20
A21: MAT-WP-007 | B21: active | C21: wallpaper | D21: 도배 | E21: 실크 | F21: 디아이디 | G21: 항균실크 | H21: 디아이디 항균실크 | I21: 표준 | J21: per_m2 | K21: 9000 | L21: 6000 | M21: =K21+L21 | N21: 시장가 추정 | O21: 2026-04 | P21: operator | Y21: =LEFT(I21,FIND(",",I21&",")-1) | Z21: =C21&"|"&Y21 | AA21: =E21&"|"&Y21
A22: MAT-WP-008 | B22: active | C22: wallpaper | D22: 도배 | E22: 실크 | F22: 개나리벽지 | G22: 패턴실크 | H22: 개나리벽지 패턴실크 | I22: 표준 | J22: per_m2 | K22: 11000 | L22: 6500 | M22: =K22+L22 | N22: 시장가 추정 | O22: 2026-04 | P22: operator | Y22: =LEFT(I22,FIND(",",I22&",")-1) | Z22: =C22&"|"&Y22 | AA22: =E22&"|"&Y22
A23: MAT-WP-009 | B23: active | C23: wallpaper | D23: 도배 | E23: 실크 | F23: LX하우시스 | G23: 디아망 | H23: LX하우시스 디아망 | I23: 고급, 주력 | J23: per_m2 | K23: 11000 | L23: 7000 | M23: =K23+L23 | N23: 시장가 추정 | O23: 2026-04 | P23: operator | Y23: =LEFT(I23,FIND(",",I23&",")-1) | Z23: =C23&"|"&Y23 | AA23: =E23&"|"&Y23
A24: MAT-WP-010 | B24: active | C24: wallpaper | D24: 도배 | E24: 실크 | F24: 디아이디 | G24: 프리미엄실크 | H24: 디아이디 프리미엄실크 | I24: 고급 | J24: per_m2 | K24: 19000 | L24: 8500 | M24: =K24+L24 | N24: 시장가 추정 | O24: 2026-04 | P24: operator | Y24: =LEFT(I24,FIND(",",I24&",")-1) | Z24: =C24&"|"&Y24 | AA24: =E24&"|"&Y24
A25: MAT-WP-011 | B25: active | C25: wallpaper | D25: 도장 | E25: 친환경도장 | F25: 벤자민무어 | G25: 친환경무광 | H25: 벤자민무어 친환경 무광 | I25: 고급 | J25: per_m2 | K25: 8000 | L25: 6500 | M25: =K25+L25 | N25: 시장가 추정 | O25: 2026-04 | P25: operator | Y25: =LEFT(I25,FIND(",",I25&",")-1) | Z25: =C25&"|"&Y25 | AA25: =E25&"|"&Y25
A26: MAT-MD-001 | B26: active | C26: molding | D26: 몰딩 | E26: PVC | F26: 비브랜드 | G26: 표준PVC | H26: PVC 평몰딩 표준 | I26: 가성비, 주력 | J26: per_m | K26: 2200 | L26: 4000 | M26: =K26+L26 | N26: 시장 시세 검증 (2026-05) | O26: 2026-05 | P26: operator | X26: SNS 단가표 (PVC 평몰딩 m당 6,000~9,000) | Y26: =LEFT(I26,FIND(",",I26&",")-1) | Z26: =C26&"|"&Y26 | AA26: =E26&"|"&Y26
A27: MAT-MD-002 | B27: active | C27: molding | D27: 몰딩 | E27: PVC | F27: 비브랜드 | G27: 슬림PVC | H27: PVC 슬림 평몰딩 | I27: 가성비 | J27: per_m | K27: 3800 | L27: 4800 | M27: =K27+L27 | N27: 시장가 추정 | O27: 2026-04 | P27: operator | Y27: =LEFT(I27,FIND(",",I27&",")-1) | Z27: =C27&"|"&Y27 | AA27: =E27&"|"&Y27
A28: MAT-MD-003 | B28: active | C28: molding | D28: 몰딩 | E28: PVC | F28: 영림 | G28: 각몰딩 | H28: 영림 PVC 각몰딩 | I28: 가성비 | J28: per_m | K28: 5500 | L28: 5500 | M28: =K28+L28 | N28: 시장가 추정 | O28: 2026-04 | P28: operator | Y28: =LEFT(I28,FIND(",",I28&",")-1) | Z28: =C28&"|"&Y28 | AA28: =E28&"|"&Y28
A29: MAT-MD-004 | B29: active | C29: molding | D29: 몰딩 | E29: MDF | F29: 대성 | G29: MDF평몰딩 | H29: 대성 MDF 평몰딩 | I29: 표준, 주력 | J29: per_m | K29: 7800 | L29: 6500 | M29: =K29+L29 | N29: 시장가 추정 | O29: 2026-04 | P29: operator | Y29: =LEFT(I29,FIND(",",I29&",")-1) | Z29: =C29&"|"&Y29 | AA29: =E29&"|"&Y29
A30: MAT-MD-005 | B30: active | C30: molding | D30: 몰딩 | E30: MDF | F30: 영림 | G30: MDF슬림 | H30: 영림 MDF 슬림 도장 | I30: 표준 | J30: per_m | K30: 9500 | L30: 7200 | M30: =K30+L30 | N30: 시장가 추정 | O30: 2026-04 | P30: operator | Y30: =LEFT(I30,FIND(",",I30&",")-1) | Z30: =C30&"|"&Y30 | AA30: =E30&"|"&Y30
A31: MAT-MD-006 | B31: active | C31: molding | D31: 몰딩 | E31: 우드 | F31: 영림 | G31: 우드몰딩 | H31: 영림 우드 평몰딩 | I31: 고급, 주력 | J31: per_m | K31: 14000 | L31: 8500 | M31: =K31+L31 | N31: 시장가 추정 | O31: 2026-04 | P31: operator | Y31: =LEFT(I31,FIND(",",I31&",")-1) | Z31: =C31&"|"&Y31 | AA31: =E31&"|"&Y31
A32: MAT-MD-007 | B32: active | C32: molding | D32: 몰딩 | E32: 마이너스 | F32: 히든몰딩 | G32: 마이너스 | H32: 히든몰딩 마이너스 | I32: 고급 | J32: per_m | K32: 18500 | L32: 12000 | M32: =K32+L32 | N32: 시장가 추정 | O32: 2026-04 | P32: operator | Y32: =LEFT(I32,FIND(",",I32&",")-1) | Z32: =C32&"|"&Y32 | AA32: =E32&"|"&Y32
A33: MAT-MD-008 | B33: active | C33: molding | D33: 몰딩 | E33: 무몰딩 | F33: 현장시공 | G33: 무몰딩 | H33: 몰딩 미시공 (목공·도배 추가비는 별도 라인으로 산정) | I33: 고급 | J33: per_m | K33: 0 | L33: 0 | M33: =K33+L33 | N33: 시장가 추정 | O33: 2026-04 | P33: operator | Y33: =LEFT(I33,FIND(",",I33&",")-1) | Z33: =C33&"|"&Y33 | AA33: =E33&"|"&Y33
A34: MAT-MX-001 | B34: active | C34: molding_carpentry | D34: 목공사 | E34: 무몰딩 | F34: 현장시공 | G34: 무몰딩목공 | H34: 무몰딩 토글 ON 시 목공사 추가비 (공급면적 ㎡당) | I34: 가성비, 주력 | J34: per_m2 | K34: 0 | L34: 10000 | M34: =K34+L34 | N34: 시장가 추정 | O34: 2026-04 | P34: operator | Y34: =LEFT(I34,FIND(",",I34&",")-1) | Z34: =C34&"|"&Y34 | AA34: =E34&"|"&Y34
A35: MAT-MX-002 | B35: active | C35: molding_carpentry | D35: 목공사 | E35: 무몰딩 | F35: 현장시공 | G35: 무몰딩목공 | H35: 무몰딩 토글 ON 시 목공사 추가비 (공급면적 ㎡당) | I35: 표준, 주력 | J35: per_m2 | K35: 0 | L35: 10000 | M35: =K35+L35 | N35: 시장가 추정 | O35: 2026-04 | P35: operator | Y35: =LEFT(I35,FIND(",",I35&",")-1) | Z35: =C35&"|"&Y35 | AA35: =E35&"|"&Y35
A36: MAT-MX-003 | B36: active | C36: molding_carpentry | D36: 목공사 | E36: 무몰딩 | F36: 현장시공 | G36: 무몰딩목공 | H36: 무몰딩 토글 ON 시 목공사 추가비 (공급면적 ㎡당) | I36: 고급, 주력 | J36: per_m2 | K36: 0 | L36: 10000 | M36: =K36+L36 | N36: 시장가 추정 | O36: 2026-04 | P36: operator | Y36: =LEFT(I36,FIND(",",I36&",")-1) | Z36: =C36&"|"&Y36 | AA36: =E36&"|"&Y36
A37: MAT-MY-001 | B37: active | C37: molding_wallpaper | D37: 몰딩 | E37: 무몰딩 | F37: 현장시공 | G37: 무몰딩도배 | H37: 무몰딩 토글 ON 시 도배 인건비 추가 (공급면적 ㎡당) | I37: 가성비, 주력 | J37: per_m2 | K37: 0 | L37: 5000 | M37: =K37+L37 | N37: 시장가 추정 | O37: 2026-04 | P37: operator | Y37: =LEFT(I37,FIND(",",I37&",")-1) | Z37: =C37&"|"&Y37 | AA37: =E37&"|"&Y37
A38: MAT-MY-002 | B38: active | C38: molding_wallpaper | D38: 몰딩 | E38: 무몰딩 | F38: 현장시공 | G38: 무몰딩도배 | H38: 무몰딩 토글 ON 시 도배 인건비 추가 (공급면적 ㎡당) | I38: 표준, 주력 | J38: per_m2 | K38: 0 | L38: 5000 | M38: =K38+L38 | N38: 시장가 추정 | O38: 2026-04 | P38: operator | Y38: =LEFT(I38,FIND(",",I38&",")-1) | Z38: =C38&"|"&Y38 | AA38: =E38&"|"&Y38
... A55: MAT-BT-001 | B55: active | C55: bath_tile | D55: 타일 | E55: 300×600각 | F55: 포스코타일 | G55: 300x600 | H55: 300×600각 욕실 타일 (자재만, 인건비는 통합 타일팀) | I55: 가성비, 주력 | J55: per_m2 | K55: 12000 | L55: 0 | M55: =K55+L55 | N55: 시장가 추정 | O55: 2026-04 | P55: operator | Y55: =LEFT(I55,FIND(",",I55&",")-1) | Z55: =C55&"|"&Y55 | AA55: =E55&"|"&Y55
A56: MAT-BT-002 | B56: active | C56: bath_tile | D56: 타일 | E56: 600각 | F56: 포세린 | G56: 600 | H56: 600×600각 포세린 타일 (자재만, 인건비는 통합 타일팀) | I56: 표준, 주력 | J56: per_m2 | K56: 30000 | L56: 0 | M56: =K56+L56 | N56: 시장 시세 검증 (2026-05) | O56: 2026-05 | P56: operator | X56: 오늘의집·셀인카페 (포세린 600각) | Y56: =LEFT(I56,FIND(",",I56&",")-1) | Z56: =C56&"|"&Y56 | AA56: =E56&"|"&Y56
...

Sheet 평형DB시나리오
A1: ▣ 평형DB 시나리오 — 자재마스터 연동 자동 산출 (24/34/44평 × 가성비/표준/고급)
A2: 평형(B4/E4/H4) 변경 시 수량 자동 갱신. 자재마스터 단가 변경 시 합계 자동 반영. 가정: 3베이.
A4: [평형 입력] | B4: 24 | E4: 34 | H4: 44 | K4: 평
A5: lower 평형대 | B5: =INT(B4/10)*10 | E5: =INT(E4/10)*10 | H5: =INT(H4/10)*10
A6: ratio | B6: =(B4-B5)/10 | E6: =(E4-E5)/10 | H6: =(H4-H5)/10
A7: lower col idx | B7: =B5/10 | E7: =E5/10 | H7: =H5/10
A8: 전용면적 (㎡) | B8: =B4*3.31*0.75 | E8: =E4*3.31*0.75 | H8: =H4*3.31*0.75
A9: 공급면적 (㎡) | B9: =B4*3.31 | E9: =E4*3.31 | H9: =H4*3.31
A10: 외부창 (㎡) | B10: =INDEX(표준면적!$B$11:$G$11,1,B7)+(INDEX(표준면적!$B$11:$G$11,1,B7+1)-INDEX(표준면적!$B$11:$G$11,1,B7))*B6 | E10: =INDEX(표준면적!$B$11:$G$11,1,E7)+(INDEX(표준면적!$B$11:$G$11,1,E7+1)-INDEX(표준면적!$B$11:$G$11,1,E7))*E6 | H10: =INDEX(표준면적!$B$11:$G$11,1,H7)+(INDEX(표준면적!$B$11:$G$11,1,H7+1)-INDEX(표준면적!$B$11:$G$11,1,H7))*H6
A11: 거실 면적 (㎡) | B11: =INDEX(표준면적!$B$3:$G$10,1,B7)+(INDEX(표준면적!$B$3:$G$10,1,B7+1)-INDEX(표준면적!$B$3:$G$10,1,B7))*B6 | E11: =INDEX(표준면적!$B$3:$G$10,1,E7)+(INDEX(표준면적!$B$3:$G$10,1,E7+1)-INDEX(표준면적!$B$3:$G$10,1,E7))*E6 | H11: =INDEX(표준면적!$B$3:$G$10,1,H7)+(INDEX(표준면적!$B$3:$G$10,1,H7+1)-INDEX(표준면적!$B$3:$G$10,1,H7))*H6
A12: 주방 면적 (㎡) | B12: =INDEX(표준면적!$B$3:$G$10,2,B7)+(INDEX(표준면적!$B$3:$G$10,2,B7+1)-INDEX(표준면적!$B$3:$G$10,2,B7))*B6 | E12: =INDEX(표준면적!$B$3:$G$10,2,E7)+(INDEX(표준면적!$B$3:$G$10,2,E7+1)-INDEX(표준면적!$B$3:$G$10,2,E7))*E6 | H12: =INDEX(표준면적!$B$3:$G$10,2,H7)+(INDEX(표준면적!$B$3:$G$10,2,H7+1)-INDEX(표준면적!$B$3:$G$10,2,H7))*H6
A13: 안방 면적 (㎡) | B13: =INDEX(표준면적!$B$3:$G$10,3,B7)+(INDEX(표준면적!$B$3:$G$10,3,B7+1)-INDEX(표준면적!$B$3:$G$10,3,B7))*B6 | E13: =INDEX(표준면적!$B$3:$G$10,3,E7)+(INDEX(표준면적!$B$3:$G$10,3,E7+1)-INDEX(표준면적!$B$3:$G$10,3,E7))*E6 | H13: =INDEX(표준면적!$B$3:$G$10,3,H7)+(INDEX(표준면적!$B$3:$G$10,3,H7+1)-INDEX(표준면적!$B$3:$G$10,3,H7))*H6
A14: 작방1 면적 (㎡) | B14: =INDEX(표준면적!$B$3:$G$10,4,B7)+(INDEX(표준면적!$B$3:$G$10,4,B7+1)-INDEX(표준면적!$B$3:$G$10,4,B7))*B6 | E14: =INDEX(표준면적!$B$3:$G$10,4,E7)+(INDEX(표준면적!$B$3:$G$10,4,E7+1)-INDEX(표준면적!$B$3:$G$10,4,E7))*E6 | H14: =INDEX(표준면적!$B$3:$G$10,4,H7)+(INDEX(표준면적!$B$3:$G$10,4,H7+1)-INDEX(표준면적!$B$3:$G$10,4,H7))*H6
A15: 작방2 면적 (㎡) | B15: =INDEX(표준면적!$B$3:$G$10,5,B7)+(INDEX(표준면적!$B$3:$G$10,5,B7+1)-INDEX(표준면적!$B$3:$G$10,5,B7))*B6 | E15: =INDEX(표준면적!$B$3:$G$10,5,E7)+(INDEX(표준면적!$B$3:$G$10,5,E7+1)-INDEX(표준면적!$B$3:$G$10,5,E7))*E6 | H15: =INDEX(표준면적!$B$3:$G$10,5,H7)+(INDEX(표준면적!$B$3:$G$10,5,H7+1)-INDEX(표준면적!$B$3:$G$10,5,H7))*H6
A16: 공용욕실 면적 (㎡) | B16: =INDEX(표준면적!$B$3:$G$10,6,B7)+(INDEX(표준면적!$B$3:$G$10,6,B7+1)-INDEX(표준면적!$B$3:$G$10,6,B7))*B6 | E16: =INDEX(표준면적!$B$3:$G$10,6,E7)+(INDEX(표준면적!$B$3:$G$10,6,E7+1)-INDEX(표준면적!$B$3:$G$10,6,E7))*E6 | H16: =INDEX(표준면적!$B$3:$G$10,6,H7)+(INDEX(표준면적!$B$3:$G$10,6,H7+1)-INDEX(표준면적!$B$3:$G$10,6,H7))*H6
A17: 부부욕실 면적 (㎡) | B17: =INDEX(표준면적!$B$3:$G$10,7,B7)+(INDEX(표준면적!$B$3:$G$10,7,B7+1)-INDEX(표준면적!$B$3:$G$10,7,B7))*B6 | E17: =INDEX(표준면적!$B$3:$G$10,7,E7)+(INDEX(표준면적!$B$3:$G$10,7,E7+1)-INDEX(표준면적!$B$3:$G$10,7,E7))*E6 | H17: =INDEX(표준면적!$B$3:$G$10,7,H7)+(INDEX(표준면적!$B$3:$G$10,7,H7+1)-INDEX(표준면적!$B$3:$G$10,7,H7))*H6
A18: 둘레 합 (몰딩, m) | B18: =SQRT(B11)*3.4+SQRT(B12)*3.4+SQRT(B13)*3.4+SQRT(B14)*3.4+SQRT(B15)*3.4 | E18: =SQRT(E11)*3.4+SQRT(E12)*3.4+SQRT(E13)*3.4+SQRT(E14)*3.4+SQRT(E15)*3.4 | H18: =SQRT(H11)*3.4+SQRT(H12)*3.4+SQRT(H13)*3.4+SQRT(H14)*3.4+SQRT(H15)*3.4
A19: 바닥 면적 합 (㎡) | B19: =B11+B12+B13+B14+B15 | E19: =E11+E12+E13+E14+E15 | H19: =H11+H12+H13+H14+H15
A20: 도배 면적 (㎡) | B20: =B19*2.8 | E20: =E19*2.8 | H20: =H19*2.8
A21: 욕실 면적 합 (㎡) | B21: =B16+B17 | E21: =E16+E17 | H21: =H16+H17
A22: 욕실 둘레 합 (m) | B22: =SQRT(B16)*3.4+SQRT(B17)*3.4 | E22: =SQRT(E16)*3.4+SQRT(E17)*3.4 | H22: =SQRT(H16)*3.4+SQRT(H17)*3.4
A23: 발코니 면적 (㎡) | B23: =INDEX(표준면적!$B$27:$G$27,1,B7)+(INDEX(표준면적!$B$27:$G$27,1,B7+1)-INDEX(표준면적!$B$27:$G$27,1,B7))*B6 | E23: =INDEX(표준면적!$B$27:$G$27,1,E7)+(INDEX(표준면적!$B$27:$G$27,1,E7+1)-INDEX(표준면적!$B$27:$G$27,1,E7))*E6 | H23: =INDEX(표준면적!$B$27:$G$27,1,H7)+(INDEX(표준면적!$B$27:$G$27,1,H7+1)-INDEX(표준면적!$B$27:$G$27,1,H7))*H6
A24: 발코니 도장 (㎡) | B24: =INDEX(표준면적!$B$29:$G$29,1,B7)+(INDEX(표준면적!$B$29:$G$29,1,B7+1)-INDEX(표준면적!$B$29:$G$29,1,B7))*B6 | E24: =INDEX(표준면적!$B$29:$G$29,1,E7)+(INDEX(표준면적!$B$29:$G$29,1,E7+1)-INDEX(표준면적!$B$29:$G$29,1,E7))*E6 | H24: =INDEX(표준면적!$B$29:$G$29,1,H7)+(INDEX(표준면적!$B$29:$G$29,1,H7+1)-INDEX(표준면적!$B$29:$G$29,1,H7))*H6
A25: 다용도실 (㎡) | B25: =INDEX(표준면적!$B$28:$G$28,1,B7)+(INDEX(표준면적!$B$28:$G$28,1,B7+1)-INDEX(표준면적!$B$28:$G$28,1,B7))*B6 | E25: =INDEX(표준면적!$B$28:$G$28,1,E7)+(INDEX(표준면적!$B$28:$G$28,1,E7+1)-INDEX(표준면적!$B$28:$G$28,1,E7))*E6 | H25: =INDEX(표준면적!$B$28:$G$28,1,H7)+(INDEX(표준면적!$B$28:$G$28,1,H7+1)-INDEX(표준면적!$B$28:$G$28,1,H7))*H6
A26: 다용도실 도장 (㎡) | B26: =INDEX(표준면적!$B$30:$G$30,1,B7)+(INDEX(표준면적!$B$30:$G$30,1,B7+1)-INDEX(표준면적!$B$30:$G$30,1,B7))*B6 | E26: =INDEX(표준면적!$B$30:$G$30,1,E7)+(INDEX(표준면적!$B$30:$G$30,1,E7+1)-INDEX(표준면적!$B$30:$G$30,1,E7))*E6 | H26: =INDEX(표준면적!$B$30:$G$30,1,H7)+(INDEX(표준면적!$B$30:$G$30,1,H7+1)-INDEX(표준면적!$B$30:$G$30,1,H7))*H6
A27: 확장 면적 (㎡) | B27: =(SQRT(B11)*1+SQRT(B14)*0.9+SQRT(B15)*0.85+SQRT(B12)*0.85)*1.5 | E27: =(SQRT(E11)*1+SQRT(E14)*0.9+SQRT(E15)*0.85+SQRT(E12)*0.85)*1.5 | H27: =(SQRT(H11)*1+SQRT(H14)*0.9+SQRT(H15)*0.85+SQRT(H12)*0.85)*1.5
A28: 발코니 합 (분배기준) | B28: =(SQRT(B11)*1+SQRT(B13)*1+SQRT(B14)*0.9+SQRT(B15)*0.85+SQRT(B12)*0.85)*1.5 | E28: =(SQRT(E11)*1+SQRT(E13)*1+SQRT(E14)*0.9+SQRT(E15)*0.85+SQRT(E12)*0.85)*1.5 | H28: =(SQRT(H11)*1+SQRT(H13)*1+SQRT(H14)*0.9+SQRT(H15)*0.85+SQRT(H12)*0.85)*1.5
A29: 외부창 확장부 비율 | B29: =B27/B28 | E29: =E27/E28 | H29: =H27/H28
A30: 스위치/콘센트 (ea) | B30: =IF(B4<15,18,IF(B4<25,24,IF(B4<35,34,IF(B4<45,42,IF(B4<55,50,56))))) | E30: =IF(E4<15,18,IF(E4<25,24,IF(E4<35,34,IF(E4<45,42,IF(E4<55,50,56))))) | H30: =IF(H4<15,18,IF(H4<25,24,IF(H4<35,34,IF(H4<45,42,IF(H4<55,50,56)))))
A31: 붙박이장 합 m | B31: =IF(B4>=40,2.4*3,IF(B4>=30,2.4+2*2,2+2*1.8)) | E31: =IF(E4>=40,2.4*3,IF(E4>=30,2.4+2*2,2+2*1.8)) | H31: =IF(H4>=40,2.4*3,IF(H4>=30,2.4+2*2,2+2*1.8))
A32: 타일팀 일수 | B32: =IF(B4<30,2,IF(B4<50,3,4))+1 | E32: =IF(E4<30,2,IF(E4<50,3,4))+1 | H32: =IF(H4<30,2,IF(H4<50,3,4))+1
A33: 다운라이트 (ea) | B33: =ROUND(B4/2.5,0) | E33: =ROUND(E4/2.5,0) | H33: =ROUND(H4/2.5,0)
A34: 난방온도조절기 (대) | B34: =IF(B4<20,2,IF(B4<30,3,IF(B4<40,4,5))) | E34: =IF(E4<20,2,IF(E4<30,3,IF(E4<40,4,5))) | H34: =IF(H4<20,2,IF(H4<30,3,IF(H4<40,4,5)))
C36: ── 24평 ── | G36: ── 34평 ── | K36: ── 44평 ──
A37: 공사 카테고리 | B37: 단위 | C37: 수량 | D37: 가성비(원) | E37: 표준(원) | F37: 고급(원) | G37: 수량 | H37: 가성비(원) | I37: 표준(원) | J37: 고급(원) | K37: 수량 | L37: 가성비(원) | M37: 표준(원) | N37: 고급(원)
A38: 철거공사 | B38: ㎡ | C38: =B8 | D38: =IFERROR(C38*INDEX(자재마스터!$M:$M,MATCH("철거|가성비",자재마스터!$AA:$AA,0)),0) | E38: =IFERROR(C38*INDEX(자재마스터!$M:$M,MATCH("철거|표준",자재마스터!$AA:$AA,0)),0) | F38: =IFERROR(C38*INDEX(자재마스터!$M:$M,MATCH("철거|고급",자재마스터!$AA:$AA,0)),0) | G38: =E8 | H38: =IFERROR(G38*INDEX(자재마스터!$M:$M,MATCH("철거|가성비",자재마스터!$AA:$AA,0)),0) | I38: =IFERROR(G38*INDEX(자재마스터!$M:$M,MATCH("철거|표준",자재마스터!$AA:$AA,0)),0) | J38: =IFERROR(G38*INDEX(자재마스터!$M:$M,MATCH("철거|고급",자재마스터!$AA:$AA,0)),0) | K38: =H8 | L38: =IFERROR(K38*INDEX(자재마스터!$M:$M,MATCH("철거|가성비",자재마스터!$AA:$AA,0)),0) | M38: =IFERROR(K38*INDEX(자재마스터!$M:$M,MATCH("철거|표준",자재마스터!$AA:$AA,0)),0) | N38: =IFERROR(K38*INDEX(자재마스터!$M:$M,MATCH("철거|고급",자재마스터!$AA:$AA,0)),0)
